2025-10-03 19:39:23 INFO     __main__ :: Run initialized at: 20251003T233923Z | Logging to: logs\generator_20251003T233923Z.log
2025-10-03 19:39:23 INFO     __main__ :: Loading Gemini API key
2025-10-03 19:39:23 INFO     __main__ :: Loading Sage API key
2025-10-03 19:39:23 INFO     __main__ :: Loading configuration from: C:\Users\zacjszewczyk\Documents\sherlock\config\generator.yml
2025-10-03 19:39:23 INFO     __main__ :: Successfully loaded configuration from 'C:\Users\zacjszewczyk\Documents\sherlock\config\generator.yml'.
2025-10-03 19:39:44 ERROR    asksageclient.client :: Error Connecting:
Traceback (most recent call last):
  File "C:\Users\zacjszewczyk\anaconda3\envs\sherlock\Lib\site-packages\urllib3\connection.py", line 198, in _new_conn
    sock = connection.create_connection(
           ^^^^^^^^^^^^^^^^^^^^^^^^^^^^^
  File "C:\Users\zacjszewczyk\anaconda3\envs\sherlock\Lib\site-packages\urllib3\util\connection.py", line 85, in create_connection
    raise err
  File "C:\Users\zacjszewczyk\anaconda3\envs\sherlock\Lib\site-packages\urllib3\util\connection.py", line 73, in create_connection
    sock.connect(sa)
TimeoutError: [WinError 10060] A connection attempt failed because the connected party did not properly respond after a period of time, or established connection failed because connected host has failed to respond

The above exception was the direct cause of the following exception:

Traceback (most recent call last):
  File "C:\Users\zacjszewczyk\anaconda3\envs\sherlock\Lib\site-packages\urllib3\connectionpool.py", line 787, in urlopen
    response = self._make_request(
               ^^^^^^^^^^^^^^^^^^^
  File "C:\Users\zacjszewczyk\anaconda3\envs\sherlock\Lib\site-packages\urllib3\connectionpool.py", line 488, in _make_request
    raise new_e
  File "C:\Users\zacjszewczyk\anaconda3\envs\sherlock\Lib\site-packages\urllib3\connectionpool.py", line 464, in _make_request
    self._validate_conn(conn)
  File "C:\Users\zacjszewczyk\anaconda3\envs\sherlock\Lib\site-packages\urllib3\connectionpool.py", line 1093, in _validate_conn
    conn.connect()
  File "C:\Users\zacjszewczyk\anaconda3\envs\sherlock\Lib\site-packages\urllib3\connection.py", line 753, in connect
    self.sock = sock = self._new_conn()
                       ^^^^^^^^^^^^^^^^
  File "C:\Users\zacjszewczyk\anaconda3\envs\sherlock\Lib\site-packages\urllib3\connection.py", line 207, in _new_conn
    raise ConnectTimeoutError(
urllib3.exceptions.ConnectTimeoutError: (<urllib3.connection.HTTPSConnection object at 0x0000020AFBEEE6F0>, 'Connection to api.genai.army.mil timed out. (connect timeout=None)')

The above exception was the direct cause of the following exception:

Traceback (most recent call last):
  File "C:\Users\zacjszewczyk\anaconda3\envs\sherlock\Lib\site-packages\requests\adapters.py", line 644, in send
    resp = conn.urlopen(
           ^^^^^^^^^^^^^
  File "C:\Users\zacjszewczyk\anaconda3\envs\sherlock\Lib\site-packages\urllib3\connectionpool.py", line 841, in urlopen
    retries = retries.increment(
              ^^^^^^^^^^^^^^^^^^
  File "C:\Users\zacjszewczyk\anaconda3\envs\sherlock\Lib\site-packages\urllib3\util\retry.py", line 519, in increment
    raise MaxRetryError(_pool, url, reason) from reason  # type: ignore[arg-type]
    ^^^^^^^^^^^^^^^^^^^^^^^^^^^^^^^^^^^^^^^^^^^^^^^^^^^
urllib3.exceptions.MaxRetryError: HTTPSConnectionPool(host='api.genai.army.mil', port=443): Max retries exceeded with url: /user//get-token-with-api-key (Caused by ConnectTimeoutError(<urllib3.connection.HTTPSConnection object at 0x0000020AFBEEE6F0>, 'Connection to api.genai.army.mil timed out. (connect timeout=None)'))

During handling of the above exception, another exception occurred:

Traceback (most recent call last):
  File "C:\Users\zacjszewczyk\anaconda3\envs\sherlock\Lib\site-packages\asksageclient\client.py", line 45, in _request
    response = requests.post(url, headers=headers, json=json, files=files, data=data)
               ^^^^^^^^^^^^^^^^^^^^^^^^^^^^^^^^^^^^^^^^^^^^^^^^^^^^^^^^^^^^^^^^^^^^^^
  File "C:\Users\zacjszewczyk\anaconda3\envs\sherlock\Lib\site-packages\requests\api.py", line 115, in post
    return request("post", url, data=data, json=json, **kwargs)
           ^^^^^^^^^^^^^^^^^^^^^^^^^^^^^^^^^^^^^^^^^^^^^^^^^^^^
  File "C:\Users\zacjszewczyk\anaconda3\envs\sherlock\Lib\site-packages\requests\api.py", line 59, in request
    return session.request(method=method, url=url, **kwargs)
           ^^^^^^^^^^^^^^^^^^^^^^^^^^^^^^^^^^^^^^^^^^^^^^^^^
  File "C:\Users\zacjszewczyk\Documents\sherlock\generator.py", line 358, in new_request
    return old_request(self, method, url, **kwargs)
           ^^^^^^^^^^^^^^^^^^^^^^^^^^^^^^^^^^^^^^^^
  File "C:\Users\zacjszewczyk\anaconda3\envs\sherlock\Lib\site-packages\requests\sessions.py", line 589, in request
    resp = self.send(prep, **send_kwargs)
           ^^^^^^^^^^^^^^^^^^^^^^^^^^^^^^
  File "C:\Users\zacjszewczyk\anaconda3\envs\sherlock\Lib\site-packages\requests\sessions.py", line 703, in send
    r = adapter.send(request, **kwargs)
        ^^^^^^^^^^^^^^^^^^^^^^^^^^^^^^^
  File "C:\Users\zacjszewczyk\anaconda3\envs\sherlock\Lib\site-packages\requests\adapters.py", line 665, in send
    raise ConnectTimeout(e, request=request)
requests.exceptions.ConnectTimeout: HTTPSConnectionPool(host='api.genai.army.mil', port=443): Max retries exceeded with url: /user//get-token-with-api-key (Caused by ConnectTimeoutError(<urllib3.connection.HTTPSConnection object at 0x0000020AFBEEE6F0>, 'Connection to api.genai.army.mil timed out. (connect timeout=None)'))
2025-10-03 19:39:44 WARNING  __main__ :: AskSage is not reachable: HTTPSConnectionPool(host='api.genai.army.mil', port=443): Max retries exceeded with url: /user//get-token-with-api-key (Caused by ConnectTimeoutError(<urllib3.connection.HTTPSConnection object at 0x0000020AFBEEE6F0>, 'Connection to api.genai.army.mil timed out. (connect timeout=None)'))
2025-10-03 19:39:44 WARNING  __main__ :: AskSage unavailable. Falling back to Gemini for this run.
2025-10-03 19:39:44 INFO     __main__ :: Building technique dictionary for ATT&CK â†’ matrix resolution
2025-10-03 19:39:44 INFO     src.attack_retriever :: Processing matrix: enterprise
2025-10-03 19:39:44 INFO     src.attack_retriever :: Using cached version of 'enterprise' matrix from 'enterprise-attack.json'.
