2025-09-29 18:10:32 INFO     __main__ :: Run initialized at: 20250929T181032Z | Logging to: logs/refiner_20250929T181032Z.log
2025-09-29 18:10:32 INFO     __main__ :: Loading Gemini API key
2025-09-29 18:10:32 INFO     __main__ :: Loading Sage API key
2025-09-29 18:10:32 INFO     __main__ :: Loading configuration
2025-09-29 18:10:32 INFO     __main__ :: Successfully loaded configuration from 'config/refine.yml'.
2025-09-29 18:10:32 INFO     __main__ :: Building technique dictionary
2025-09-29 18:10:32 INFO     src.attack_retriever :: Processing matrix: mobile
2025-09-29 18:10:32 INFO     src.attack_retriever :: Using cached version of 'mobile' matrix from 'mobile-attack.json'.
2025-09-29 18:10:33 INFO     src.attack_retriever :: Built dictionary with 121 unique techniques across 1 matrices.
2025-09-29 18:10:33 INFO     __main__ :: Will attempt to refine plans for up to 121 techniques (existing files only).
2025-09-29 18:10:33 INFO     __main__ :: [MAIN pid=66871 proc=MainProcess] Running in multi-core mode with 8 workers.
2025-09-29 18:10:44 INFO     __main__ :: [T1663] [pid=66882 proc=ForkProcess-4] START: about to process with endpoint=gemini model=gemini-2.5-flash
2025-09-29 18:10:44 INFO     __main__ :: [LLM] [pid=66882 proc=ForkProcess-4] Attempt 1/3: endpoint=gemini model=gemini-2.5-flash
2025-09-29 18:10:44 INFO     google_genai.models :: AFC is enabled with max remote calls: 10.
2025-09-29 18:10:44 INFO     httpx :: HTTP Request: POST https://generativelanguage.googleapis.com/v1beta/models/gemini-2.5-flash:generateContent "HTTP/1.1 500 Internal Server Error"
2025-09-29 18:10:44 WARNING  __main__ :: [LLM] [pid=66882 proc=ForkProcess-4] Gemini error: 500 INTERNAL. {'error': {'code': 500, 'message': 'An internal error has occurred. Please retry or report in https://developers.generativeai.google/guide/troubleshooting', 'status': 'INTERNAL'}}. Retrying in 1.0s ...
2025-09-29 18:10:45 INFO     __main__ :: [LLM] [pid=66882 proc=ForkProcess-4] Attempt 2/3: endpoint=gemini model=gemini-2.5-flash
2025-09-29 18:10:45 INFO     google_genai.models :: AFC is enabled with max remote calls: 10.
2025-09-29 18:10:46 INFO     httpx :: HTTP Request: POST https://generativelanguage.googleapis.com/v1beta/models/gemini-2.5-flash:generateContent "HTTP/1.1 500 Internal Server Error"
2025-09-29 18:10:46 WARNING  __main__ :: [LLM] [pid=66882 proc=ForkProcess-4] Gemini error: 500 INTERNAL. {'error': {'code': 500, 'message': 'An internal error has occurred. Please retry or report in https://developers.generativeai.google/guide/troubleshooting', 'status': 'INTERNAL'}}. Retrying in 2.0s ...
2025-09-29 18:10:48 INFO     __main__ :: [LLM] [pid=66882 proc=ForkProcess-4] Attempt 3/3: endpoint=gemini model=gemini-2.5-flash
2025-09-29 18:10:48 INFO     google_genai.models :: AFC is enabled with max remote calls: 10.
2025-09-29 18:10:48 INFO     httpx :: HTTP Request: POST https://generativelanguage.googleapis.com/v1beta/models/gemini-2.5-flash:generateContent "HTTP/1.1 429 Too Many Requests"
2025-09-29 18:10:48 ERROR    __main__ :: [LLM] [pid=66882 proc=ForkProcess-4] Gemini rate/quota issue: 429 RESOURCE_EXHAUSTED. {'error': {'code': 429, 'message': 'You exceeded your current quota, please check your plan and billing details. For more information on this error, head to: https://ai.google.dev/gemini-api/docs/rate-limits.\n* Quota exceeded for metric: generativelanguage.googleapis.com/generate_content_free_tier_requests, limit: 250\nPlease retry in 11.588341895s.', 'status': 'RESOURCE_EXHAUSTED', 'details': [{'@type': 'type.googleapis.com/google.rpc.QuotaFailure', 'violations': [{'quotaMetric': 'generativelanguage.googleapis.com/generate_content_free_tier_requests', 'quotaId': 'GenerateRequestsPerDayPerProjectPerModel-FreeTier', 'quotaDimensions': {'location': 'global', 'model': 'gemini-2.5-flash'}, 'quotaValue': '250'}]}, {'@type': 'type.googleapis.com/google.rpc.Help', 'links': [{'description': 'Learn more about Gemini API quotas', 'url': 'https://ai.google.dev/gemini-api/docs/rate-limits'}]}, {'@type': 'type.googleapis.com/google.rpc.RetryInfo', 'retryDelay': '11s'}]}}. Falling back to AskSage.
2025-09-29 18:10:48 INFO     __main__ :: [LLM] [pid=66882 proc=ForkProcess-4] Using endpoint=AskSage model=google-gemini-2.5-pro
2025-09-29 18:10:53 INFO     __main__ :: [T1630.001] [pid=66883 proc=ForkProcess-5] START: about to process with endpoint=gemini model=gemini-2.5-flash
2025-09-29 18:10:53 INFO     __main__ :: [LLM] [pid=66883 proc=ForkProcess-5] Attempt 1/3: endpoint=gemini model=gemini-2.5-flash
2025-09-29 18:10:53 INFO     google_genai.models :: AFC is enabled with max remote calls: 10.
2025-09-29 18:10:54 INFO     __main__ :: [T1638] [pid=66880 proc=ForkProcess-2] START: about to process with endpoint=gemini model=gemini-2.5-flash
2025-09-29 18:10:54 INFO     __main__ :: [LLM] [pid=66880 proc=ForkProcess-2] Attempt 1/3: endpoint=gemini model=gemini-2.5-flash
2025-09-29 18:10:54 INFO     __main__ :: [T1630] [pid=66884 proc=ForkProcess-6] START: about to process with endpoint=gemini model=gemini-2.5-flash
2025-09-29 18:10:54 INFO     __main__ :: [LLM] [pid=66884 proc=ForkProcess-6] Attempt 1/3: endpoint=gemini model=gemini-2.5-flash
2025-09-29 18:10:54 INFO     google_genai.models :: AFC is enabled with max remote calls: 10.
2025-09-29 18:10:54 INFO     google_genai.models :: AFC is enabled with max remote calls: 10.
2025-09-29 18:10:54 INFO     httpx :: HTTP Request: POST https://generativelanguage.googleapis.com/v1beta/models/gemini-2.5-flash:generateContent "HTTP/1.1 429 Too Many Requests"
2025-09-29 18:10:54 ERROR    __main__ :: [LLM] [pid=66880 proc=ForkProcess-2] Gemini rate/quota issue: 429 RESOURCE_EXHAUSTED. {'error': {'code': 429, 'message': 'You exceeded your current quota, please check your plan and billing details. For more information on this error, head to: https://ai.google.dev/gemini-api/docs/rate-limits.\n* Quota exceeded for metric: generativelanguage.googleapis.com/generate_content_free_tier_requests, limit: 250\nPlease retry in 5.387380122s.', 'status': 'RESOURCE_EXHAUSTED', 'details': [{'@type': 'type.googleapis.com/google.rpc.QuotaFailure', 'violations': [{'quotaMetric': 'generativelanguage.googleapis.com/generate_content_free_tier_requests', 'quotaId': 'GenerateRequestsPerDayPerProjectPerModel-FreeTier', 'quotaDimensions': {'location': 'global', 'model': 'gemini-2.5-flash'}, 'quotaValue': '250'}]}, {'@type': 'type.googleapis.com/google.rpc.Help', 'links': [{'description': 'Learn more about Gemini API quotas', 'url': 'https://ai.google.dev/gemini-api/docs/rate-limits'}]}, {'@type': 'type.googleapis.com/google.rpc.RetryInfo', 'retryDelay': '5s'}]}}. Falling back to AskSage.
2025-09-29 18:10:54 INFO     __main__ :: [LLM] [pid=66880 proc=ForkProcess-2] Using endpoint=AskSage model=google-gemini-2.5-pro
2025-09-29 18:10:54 INFO     httpx :: HTTP Request: POST https://generativelanguage.googleapis.com/v1beta/models/gemini-2.5-flash:generateContent "HTTP/1.1 429 Too Many Requests"
2025-09-29 18:10:54 ERROR    __main__ :: [LLM] [pid=66884 proc=ForkProcess-6] Gemini rate/quota issue: 429 RESOURCE_EXHAUSTED. {'error': {'code': 429, 'message': 'You exceeded your current quota, please check your plan and billing details. For more information on this error, head to: https://ai.google.dev/gemini-api/docs/rate-limits.\n* Quota exceeded for metric: generativelanguage.googleapis.com/generate_content_free_tier_requests, limit: 250\nPlease retry in 5.359338604s.', 'status': 'RESOURCE_EXHAUSTED', 'details': [{'@type': 'type.googleapis.com/google.rpc.QuotaFailure', 'violations': [{'quotaMetric': 'generativelanguage.googleapis.com/generate_content_free_tier_requests', 'quotaId': 'GenerateRequestsPerDayPerProjectPerModel-FreeTier', 'quotaDimensions': {'model': 'gemini-2.5-flash', 'location': 'global'}, 'quotaValue': '250'}]}, {'@type': 'type.googleapis.com/google.rpc.Help', 'links': [{'description': 'Learn more about Gemini API quotas', 'url': 'https://ai.google.dev/gemini-api/docs/rate-limits'}]}, {'@type': 'type.googleapis.com/google.rpc.RetryInfo', 'retryDelay': '5s'}]}}. Falling back to AskSage.
2025-09-29 18:10:54 INFO     __main__ :: [LLM] [pid=66884 proc=ForkProcess-6] Using endpoint=AskSage model=google-gemini-2.5-pro
2025-09-29 18:10:54 INFO     httpx :: HTTP Request: POST https://generativelanguage.googleapis.com/v1beta/models/gemini-2.5-flash:generateContent "HTTP/1.1 500 Internal Server Error"
2025-09-29 18:10:54 WARNING  __main__ :: [LLM] [pid=66883 proc=ForkProcess-5] Gemini error: 500 INTERNAL. {'error': {'code': 500, 'message': 'An internal error has occurred. Please retry or report in https://developers.generativeai.google/guide/troubleshooting', 'status': 'INTERNAL'}}. Retrying in 1.0s ...
2025-09-29 18:10:55 INFO     __main__ :: [LLM] [pid=66883 proc=ForkProcess-5] Attempt 2/3: endpoint=gemini model=gemini-2.5-flash
2025-09-29 18:10:55 INFO     google_genai.models :: AFC is enabled with max remote calls: 10.
2025-09-29 18:10:55 INFO     httpx :: HTTP Request: POST https://generativelanguage.googleapis.com/v1beta/models/gemini-2.5-flash:generateContent "HTTP/1.1 429 Too Many Requests"
2025-09-29 18:10:55 ERROR    __main__ :: [LLM] [pid=66883 proc=ForkProcess-5] Gemini rate/quota issue: 429 RESOURCE_EXHAUSTED. {'error': {'code': 429, 'message': 'You exceeded your current quota, please check your plan and billing details. For more information on this error, head to: https://ai.google.dev/gemini-api/docs/rate-limits.\n* Quota exceeded for metric: generativelanguage.googleapis.com/generate_content_free_tier_requests, limit: 250\nPlease retry in 4.096375635s.', 'status': 'RESOURCE_EXHAUSTED', 'details': [{'@type': 'type.googleapis.com/google.rpc.QuotaFailure', 'violations': [{'quotaMetric': 'generativelanguage.googleapis.com/generate_content_free_tier_requests', 'quotaId': 'GenerateRequestsPerDayPerProjectPerModel-FreeTier', 'quotaDimensions': {'location': 'global', 'model': 'gemini-2.5-flash'}, 'quotaValue': '250'}]}, {'@type': 'type.googleapis.com/google.rpc.Help', 'links': [{'description': 'Learn more about Gemini API quotas', 'url': 'https://ai.google.dev/gemini-api/docs/rate-limits'}]}, {'@type': 'type.googleapis.com/google.rpc.RetryInfo', 'retryDelay': '4s'}]}}. Falling back to AskSage.
2025-09-29 18:10:55 INFO     __main__ :: [LLM] [pid=66883 proc=ForkProcess-5] Using endpoint=AskSage model=google-gemini-2.5-pro
2025-09-29 18:11:02 INFO     __main__ :: [T1474] [pid=66885 proc=ForkProcess-7] START: about to process with endpoint=gemini model=gemini-2.5-flash
2025-09-29 18:11:02 INFO     __main__ :: [LLM] [pid=66885 proc=ForkProcess-7] Attempt 1/3: endpoint=gemini model=gemini-2.5-flash
2025-09-29 18:11:02 INFO     google_genai.models :: AFC is enabled with max remote calls: 10.
2025-09-29 18:11:02 INFO     httpx :: HTTP Request: POST https://generativelanguage.googleapis.com/v1beta/models/gemini-2.5-flash:generateContent "HTTP/1.1 429 Too Many Requests"
2025-09-29 18:11:02 ERROR    __main__ :: [LLM] [pid=66885 proc=ForkProcess-7] Gemini rate/quota issue: 429 RESOURCE_EXHAUSTED. {'error': {'code': 429, 'message': 'You exceeded your current quota, please check your plan and billing details. For more information on this error, head to: https://ai.google.dev/gemini-api/docs/rate-limits.\n* Quota exceeded for metric: generativelanguage.googleapis.com/generate_content_free_tier_requests, limit: 250\nPlease retry in 57.281089945s.', 'status': 'RESOURCE_EXHAUSTED', 'details': [{'@type': 'type.googleapis.com/google.rpc.QuotaFailure', 'violations': [{'quotaMetric': 'generativelanguage.googleapis.com/generate_content_free_tier_requests', 'quotaId': 'GenerateRequestsPerDayPerProjectPerModel-FreeTier', 'quotaDimensions': {'location': 'global', 'model': 'gemini-2.5-flash'}, 'quotaValue': '250'}]}, {'@type': 'type.googleapis.com/google.rpc.Help', 'links': [{'description': 'Learn more about Gemini API quotas', 'url': 'https://ai.google.dev/gemini-api/docs/rate-limits'}]}, {'@type': 'type.googleapis.com/google.rpc.RetryInfo', 'retryDelay': '57s'}]}}. Falling back to AskSage.
2025-09-29 18:11:02 INFO     __main__ :: [LLM] [pid=66885 proc=ForkProcess-7] Using endpoint=AskSage model=google-gemini-2.5-pro
2025-09-29 18:11:03 INFO     __main__ :: [T1603] [pid=66879 proc=ForkProcess-1] START: about to process with endpoint=gemini model=gemini-2.5-flash
2025-09-29 18:11:03 INFO     __main__ :: [LLM] [pid=66879 proc=ForkProcess-1] Attempt 1/3: endpoint=gemini model=gemini-2.5-flash
2025-09-29 18:11:03 INFO     google_genai.models :: AFC is enabled with max remote calls: 10.
2025-09-29 18:11:03 INFO     httpx :: HTTP Request: POST https://generativelanguage.googleapis.com/v1beta/models/gemini-2.5-flash:generateContent "HTTP/1.1 429 Too Many Requests"
2025-09-29 18:11:03 ERROR    __main__ :: [LLM] [pid=66879 proc=ForkProcess-1] Gemini rate/quota issue: 429 RESOURCE_EXHAUSTED. {'error': {'code': 429, 'message': 'You exceeded your current quota, please check your plan and billing details. For more information on this error, head to: https://ai.google.dev/gemini-api/docs/rate-limits.\n* Quota exceeded for metric: generativelanguage.googleapis.com/generate_content_free_tier_requests, limit: 250\nPlease retry in 56.849318408s.', 'status': 'RESOURCE_EXHAUSTED', 'details': [{'@type': 'type.googleapis.com/google.rpc.QuotaFailure', 'violations': [{'quotaMetric': 'generativelanguage.googleapis.com/generate_content_free_tier_requests', 'quotaId': 'GenerateRequestsPerDayPerProjectPerModel-FreeTier', 'quotaDimensions': {'location': 'global', 'model': 'gemini-2.5-flash'}, 'quotaValue': '250'}]}, {'@type': 'type.googleapis.com/google.rpc.Help', 'links': [{'description': 'Learn more about Gemini API quotas', 'url': 'https://ai.google.dev/gemini-api/docs/rate-limits'}]}, {'@type': 'type.googleapis.com/google.rpc.RetryInfo', 'retryDelay': '56s'}]}}. Falling back to AskSage.
2025-09-29 18:11:03 INFO     __main__ :: [LLM] [pid=66879 proc=ForkProcess-1] Using endpoint=AskSage model=google-gemini-2.5-pro
2025-09-29 18:11:05 INFO     __main__ :: [T1626] [pid=66881 proc=ForkProcess-3] START: about to process with endpoint=gemini model=gemini-2.5-flash
2025-09-29 18:11:05 INFO     __main__ :: [LLM] [pid=66881 proc=ForkProcess-3] Attempt 1/3: endpoint=gemini model=gemini-2.5-flash
2025-09-29 18:11:05 INFO     google_genai.models :: AFC is enabled with max remote calls: 10.
2025-09-29 18:11:05 INFO     httpx :: HTTP Request: POST https://generativelanguage.googleapis.com/v1beta/models/gemini-2.5-flash:generateContent "HTTP/1.1 429 Too Many Requests"
2025-09-29 18:11:05 ERROR    __main__ :: [LLM] [pid=66881 proc=ForkProcess-3] Gemini rate/quota issue: 429 RESOURCE_EXHAUSTED. {'error': {'code': 429, 'message': 'You exceeded your current quota, please check your plan and billing details. For more information on this error, head to: https://ai.google.dev/gemini-api/docs/rate-limits.\n* Quota exceeded for metric: generativelanguage.googleapis.com/generate_content_free_tier_requests, limit: 250\nPlease retry in 54.559707812s.', 'status': 'RESOURCE_EXHAUSTED', 'details': [{'@type': 'type.googleapis.com/google.rpc.QuotaFailure', 'violations': [{'quotaMetric': 'generativelanguage.googleapis.com/generate_content_free_tier_requests', 'quotaId': 'GenerateRequestsPerDayPerProjectPerModel-FreeTier', 'quotaDimensions': {'model': 'gemini-2.5-flash', 'location': 'global'}, 'quotaValue': '250'}]}, {'@type': 'type.googleapis.com/google.rpc.Help', 'links': [{'description': 'Learn more about Gemini API quotas', 'url': 'https://ai.google.dev/gemini-api/docs/rate-limits'}]}, {'@type': 'type.googleapis.com/google.rpc.RetryInfo', 'retryDelay': '54s'}]}}. Falling back to AskSage.
2025-09-29 18:11:05 INFO     __main__ :: [LLM] [pid=66881 proc=ForkProcess-3] Using endpoint=AskSage model=google-gemini-2.5-pro
2025-09-29 18:11:19 INFO     __main__ :: [T1430.002] [pid=66886 proc=ForkProcess-8] START: about to process with endpoint=gemini model=gemini-2.5-flash
2025-09-29 18:11:19 INFO     __main__ :: [LLM] [pid=66886 proc=ForkProcess-8] Attempt 1/3: endpoint=gemini model=gemini-2.5-flash
2025-09-29 18:11:19 INFO     google_genai.models :: AFC is enabled with max remote calls: 10.
2025-09-29 18:11:19 INFO     httpx :: HTTP Request: POST https://generativelanguage.googleapis.com/v1beta/models/gemini-2.5-flash:generateContent "HTTP/1.1 429 Too Many Requests"
2025-09-29 18:11:19 ERROR    __main__ :: [LLM] [pid=66886 proc=ForkProcess-8] Gemini rate/quota issue: 429 RESOURCE_EXHAUSTED. {'error': {'code': 429, 'message': 'You exceeded your current quota, please check your plan and billing details. For more information on this error, head to: https://ai.google.dev/gemini-api/docs/rate-limits.\n* Quota exceeded for metric: generativelanguage.googleapis.com/generate_content_free_tier_requests, limit: 250\nPlease retry in 40.200600821s.', 'status': 'RESOURCE_EXHAUSTED', 'details': [{'@type': 'type.googleapis.com/google.rpc.QuotaFailure', 'violations': [{'quotaMetric': 'generativelanguage.googleapis.com/generate_content_free_tier_requests', 'quotaId': 'GenerateRequestsPerDayPerProjectPerModel-FreeTier', 'quotaDimensions': {'model': 'gemini-2.5-flash', 'location': 'global'}, 'quotaValue': '250'}]}, {'@type': 'type.googleapis.com/google.rpc.Help', 'links': [{'description': 'Learn more about Gemini API quotas', 'url': 'https://ai.google.dev/gemini-api/docs/rate-limits'}]}, {'@type': 'type.googleapis.com/google.rpc.RetryInfo', 'retryDelay': '40s'}]}}. Falling back to AskSage.
2025-09-29 18:11:19 INFO     __main__ :: [LLM] [pid=66886 proc=ForkProcess-8] Using endpoint=AskSage model=google-gemini-2.5-pro
2025-09-29 18:14:02 INFO     __main__ :: [LLM] [pid=66884 proc=ForkProcess-6] AskSage success model=google-gemini-2.5-pro
2025-09-29 18:14:02 INFO     __main__ :: [T1630] [pid=66884 proc=ForkProcess-6] INFO: fell back to endpoint=asksage model=google-gemini-2.5-pro
2025-09-29 18:14:02 INFO     __main__ :: [T1630] [pid=66884 proc=ForkProcess-6] DONE: processing complete with endpoint=asksage model=google-gemini-2.5-pro
2025-09-29 18:14:02 INFO     __main__ :: [MAIN pid=66871 proc=MainProcess] T1630: ok
2025-09-29 18:15:03 ERROR    __main__ :: [MAIN pid=66871 proc=MainProcess] Worker crashed: Error getting access token
2025-09-29 18:15:26 INFO     __main__ :: [LLM] [pid=66881 proc=ForkProcess-3] AskSage success model=google-gemini-2.5-pro
2025-09-29 18:15:26 INFO     __main__ :: [T1626] [pid=66881 proc=ForkProcess-3] INFO: fell back to endpoint=asksage model=google-gemini-2.5-pro
2025-09-29 18:15:26 INFO     __main__ :: [T1626] [pid=66881 proc=ForkProcess-3] DONE: processing complete with endpoint=asksage model=google-gemini-2.5-pro
2025-09-29 18:15:26 INFO     __main__ :: [MAIN pid=66871 proc=MainProcess] T1626: ok
2025-09-29 18:15:27 ERROR    asksageclient.client :: Http Error:
Traceback (most recent call last):
  File "/home/jupyter-zszewczyk/.conda/envs/watson/lib/python3.12/site-packages/asksageclient/client.py", line 46, in _request
    response.raise_for_status()
  File "/home/jupyter-zszewczyk/.conda/envs/watson/lib/python3.12/site-packages/requests/models.py", line 1026, in raise_for_status
    raise HTTPError(http_error_msg, response=self)
requests.exceptions.HTTPError: 503 Server Error: Service Unavailable for url: https://api.genai.army.mil/user//get-token-with-api-key
2025-09-29 18:15:27 ERROR    __main__ :: [MAIN pid=66871 proc=MainProcess] Worker crashed: 503 Server Error: Service Unavailable for url: https://api.genai.army.mil/user//get-token-with-api-key
2025-09-29 18:15:28 ERROR    asksageclient.client :: Http Error:
Traceback (most recent call last):
  File "/home/jupyter-zszewczyk/.conda/envs/watson/lib/python3.12/site-packages/asksageclient/client.py", line 46, in _request
    response.raise_for_status()
  File "/home/jupyter-zszewczyk/.conda/envs/watson/lib/python3.12/site-packages/requests/models.py", line 1026, in raise_for_status
    raise HTTPError(http_error_msg, response=self)
requests.exceptions.HTTPError: 503 Server Error: Service Unavailable for url: https://api.genai.army.mil/user//get-token-with-api-key
2025-09-29 18:15:28 ERROR    __main__ :: [MAIN pid=66871 proc=MainProcess] Worker crashed: 503 Server Error: Service Unavailable for url: https://api.genai.army.mil/user//get-token-with-api-key
2025-09-29 18:15:28 ERROR    asksageclient.client :: Http Error:
Traceback (most recent call last):
  File "/home/jupyter-zszewczyk/.conda/envs/watson/lib/python3.12/site-packages/asksageclient/client.py", line 46, in _request
    response.raise_for_status()
  File "/home/jupyter-zszewczyk/.conda/envs/watson/lib/python3.12/site-packages/requests/models.py", line 1026, in raise_for_status
    raise HTTPError(http_error_msg, response=self)
requests.exceptions.HTTPError: 503 Server Error: Service Unavailable for url: https://api.genai.army.mil/user//get-token-with-api-key
2025-09-29 18:15:28 ERROR    __main__ :: [MAIN pid=66871 proc=MainProcess] Worker crashed: 503 Server Error: Service Unavailable for url: https://api.genai.army.mil/user//get-token-with-api-key
2025-09-29 18:15:28 ERROR    asksageclient.client :: Http Error:
Traceback (most recent call last):
  File "/home/jupyter-zszewczyk/.conda/envs/watson/lib/python3.12/site-packages/asksageclient/client.py", line 46, in _request
    response.raise_for_status()
  File "/home/jupyter-zszewczyk/.conda/envs/watson/lib/python3.12/site-packages/requests/models.py", line 1026, in raise_for_status
    raise HTTPError(http_error_msg, response=self)
requests.exceptions.HTTPError: 503 Server Error: Service Temporarily Unavailable for url: https://api.genai.army.mil/user//get-token-with-api-key
2025-09-29 18:15:28 ERROR    __main__ :: [MAIN pid=66871 proc=MainProcess] Worker crashed: 503 Server Error: Service Temporarily Unavailable for url: https://api.genai.army.mil/user//get-token-with-api-key
2025-09-29 18:15:28 ERROR    asksageclient.client :: Http Error:
Traceback (most recent call last):
  File "/home/jupyter-zszewczyk/.conda/envs/watson/lib/python3.12/site-packages/asksageclient/client.py", line 46, in _request
    response.raise_for_status()
  File "/home/jupyter-zszewczyk/.conda/envs/watson/lib/python3.12/site-packages/requests/models.py", line 1026, in raise_for_status
    raise HTTPError(http_error_msg, response=self)
requests.exceptions.HTTPError: 503 Server Error: Service Unavailable for url: https://api.genai.army.mil/user//get-token-with-api-key
2025-09-29 18:15:28 ERROR    __main__ :: [MAIN pid=66871 proc=MainProcess] Worker crashed: 503 Server Error: Service Unavailable for url: https://api.genai.army.mil/user//get-token-with-api-key
2025-09-29 18:15:28 ERROR    asksageclient.client :: Http Error:
Traceback (most recent call last):
  File "/home/jupyter-zszewczyk/.conda/envs/watson/lib/python3.12/site-packages/asksageclient/client.py", line 46, in _request
    response.raise_for_status()
  File "/home/jupyter-zszewczyk/.conda/envs/watson/lib/python3.12/site-packages/requests/models.py", line 1026, in raise_for_status
    raise HTTPError(http_error_msg, response=self)
requests.exceptions.HTTPError: 503 Server Error: Service Temporarily Unavailable for url: https://api.genai.army.mil/user//get-token-with-api-key
2025-09-29 18:15:28 ERROR    __main__ :: [MAIN pid=66871 proc=MainProcess] Worker crashed: 503 Server Error: Service Temporarily Unavailable for url: https://api.genai.army.mil/user//get-token-with-api-key
2025-09-29 18:15:29 ERROR    asksageclient.client :: Http Error:
Traceback (most recent call last):
  File "/home/jupyter-zszewczyk/.conda/envs/watson/lib/python3.12/site-packages/asksageclient/client.py", line 46, in _request
    response.raise_for_status()
  File "/home/jupyter-zszewczyk/.conda/envs/watson/lib/python3.12/site-packages/requests/models.py", line 1026, in raise_for_status
    raise HTTPError(http_error_msg, response=self)
requests.exceptions.HTTPError: 503 Server Error: Service Temporarily Unavailable for url: https://api.genai.army.mil/user//get-token-with-api-key
2025-09-29 18:15:29 ERROR    __main__ :: [MAIN pid=66871 proc=MainProcess] Worker crashed: 503 Server Error: Service Temporarily Unavailable for url: https://api.genai.army.mil/user//get-token-with-api-key
2025-09-29 18:15:29 ERROR    asksageclient.client :: Http Error:
Traceback (most recent call last):
  File "/home/jupyter-zszewczyk/.conda/envs/watson/lib/python3.12/site-packages/asksageclient/client.py", line 46, in _request
    response.raise_for_status()
  File "/home/jupyter-zszewczyk/.conda/envs/watson/lib/python3.12/site-packages/requests/models.py", line 1026, in raise_for_status
    raise HTTPError(http_error_msg, response=self)
requests.exceptions.HTTPError: 503 Server Error: Service Temporarily Unavailable for url: https://api.genai.army.mil/user//get-token-with-api-key
2025-09-29 18:15:29 ERROR    __main__ :: [MAIN pid=66871 proc=MainProcess] Worker crashed: 503 Server Error: Service Temporarily Unavailable for url: https://api.genai.army.mil/user//get-token-with-api-key
2025-09-29 18:15:29 ERROR    asksageclient.client :: Http Error:
Traceback (most recent call last):
  File "/home/jupyter-zszewczyk/.conda/envs/watson/lib/python3.12/site-packages/asksageclient/client.py", line 46, in _request
    response.raise_for_status()
  File "/home/jupyter-zszewczyk/.conda/envs/watson/lib/python3.12/site-packages/requests/models.py", line 1026, in raise_for_status
    raise HTTPError(http_error_msg, response=self)
requests.exceptions.HTTPError: 503 Server Error: Service Temporarily Unavailable for url: https://api.genai.army.mil/user//get-token-with-api-key
2025-09-29 18:15:29 ERROR    __main__ :: [MAIN pid=66871 proc=MainProcess] Worker crashed: 503 Server Error: Service Temporarily Unavailable for url: https://api.genai.army.mil/user//get-token-with-api-key
2025-09-29 18:15:29 ERROR    asksageclient.client :: Http Error:
Traceback (most recent call last):
  File "/home/jupyter-zszewczyk/.conda/envs/watson/lib/python3.12/site-packages/asksageclient/client.py", line 46, in _request
    response.raise_for_status()
  File "/home/jupyter-zszewczyk/.conda/envs/watson/lib/python3.12/site-packages/requests/models.py", line 1026, in raise_for_status
    raise HTTPError(http_error_msg, response=self)
requests.exceptions.HTTPError: 503 Server Error: Service Temporarily Unavailable for url: https://api.genai.army.mil/user//get-token-with-api-key
2025-09-29 18:15:29 ERROR    __main__ :: [MAIN pid=66871 proc=MainProcess] Worker crashed: 503 Server Error: Service Temporarily Unavailable for url: https://api.genai.army.mil/user//get-token-with-api-key
2025-09-29 18:15:29 ERROR    asksageclient.client :: Http Error:
Traceback (most recent call last):
  File "/home/jupyter-zszewczyk/.conda/envs/watson/lib/python3.12/site-packages/asksageclient/client.py", line 46, in _request
    response.raise_for_status()
  File "/home/jupyter-zszewczyk/.conda/envs/watson/lib/python3.12/site-packages/requests/models.py", line 1026, in raise_for_status
    raise HTTPError(http_error_msg, response=self)
requests.exceptions.HTTPError: 503 Server Error: Service Temporarily Unavailable for url: https://api.genai.army.mil/user//get-token-with-api-key
2025-09-29 18:15:29 ERROR    __main__ :: [MAIN pid=66871 proc=MainProcess] Worker crashed: 503 Server Error: Service Temporarily Unavailable for url: https://api.genai.army.mil/user//get-token-with-api-key
2025-09-29 18:15:29 ERROR    asksageclient.client :: Http Error:
Traceback (most recent call last):
  File "/home/jupyter-zszewczyk/.conda/envs/watson/lib/python3.12/site-packages/asksageclient/client.py", line 46, in _request
    response.raise_for_status()
  File "/home/jupyter-zszewczyk/.conda/envs/watson/lib/python3.12/site-packages/requests/models.py", line 1026, in raise_for_status
    raise HTTPError(http_error_msg, response=self)
requests.exceptions.HTTPError: 503 Server Error: Service Temporarily Unavailable for url: https://api.genai.army.mil/user//get-token-with-api-key
2025-09-29 18:15:29 ERROR    __main__ :: [MAIN pid=66871 proc=MainProcess] Worker crashed: 503 Server Error: Service Temporarily Unavailable for url: https://api.genai.army.mil/user//get-token-with-api-key
2025-09-29 18:15:29 ERROR    asksageclient.client :: Http Error:
Traceback (most recent call last):
  File "/home/jupyter-zszewczyk/.conda/envs/watson/lib/python3.12/site-packages/asksageclient/client.py", line 46, in _request
    response.raise_for_status()
  File "/home/jupyter-zszewczyk/.conda/envs/watson/lib/python3.12/site-packages/requests/models.py", line 1026, in raise_for_status
    raise HTTPError(http_error_msg, response=self)
requests.exceptions.HTTPError: 503 Server Error: Service Temporarily Unavailable for url: https://api.genai.army.mil/user//get-token-with-api-key
2025-09-29 18:15:29 ERROR    __main__ :: [MAIN pid=66871 proc=MainProcess] Worker crashed: 503 Server Error: Service Temporarily Unavailable for url: https://api.genai.army.mil/user//get-token-with-api-key
2025-09-29 18:15:30 ERROR    asksageclient.client :: Http Error:
Traceback (most recent call last):
  File "/home/jupyter-zszewczyk/.conda/envs/watson/lib/python3.12/site-packages/asksageclient/client.py", line 46, in _request
    response.raise_for_status()
  File "/home/jupyter-zszewczyk/.conda/envs/watson/lib/python3.12/site-packages/requests/models.py", line 1026, in raise_for_status
    raise HTTPError(http_error_msg, response=self)
requests.exceptions.HTTPError: 503 Server Error: Service Temporarily Unavailable for url: https://api.genai.army.mil/user//get-token-with-api-key
2025-09-29 18:15:30 ERROR    __main__ :: [MAIN pid=66871 proc=MainProcess] Worker crashed: 503 Server Error: Service Temporarily Unavailable for url: https://api.genai.army.mil/user//get-token-with-api-key
2025-09-29 18:15:30 ERROR    asksageclient.client :: Http Error:
Traceback (most recent call last):
  File "/home/jupyter-zszewczyk/.conda/envs/watson/lib/python3.12/site-packages/asksageclient/client.py", line 46, in _request
    response.raise_for_status()
  File "/home/jupyter-zszewczyk/.conda/envs/watson/lib/python3.12/site-packages/requests/models.py", line 1026, in raise_for_status
    raise HTTPError(http_error_msg, response=self)
requests.exceptions.HTTPError: 503 Server Error: Service Temporarily Unavailable for url: https://api.genai.army.mil/user//get-token-with-api-key
2025-09-29 18:15:30 ERROR    __main__ :: [MAIN pid=66871 proc=MainProcess] Worker crashed: 503 Server Error: Service Temporarily Unavailable for url: https://api.genai.army.mil/user//get-token-with-api-key
2025-09-29 18:15:30 ERROR    asksageclient.client :: Http Error:
Traceback (most recent call last):
  File "/home/jupyter-zszewczyk/.conda/envs/watson/lib/python3.12/site-packages/asksageclient/client.py", line 46, in _request
    response.raise_for_status()
  File "/home/jupyter-zszewczyk/.conda/envs/watson/lib/python3.12/site-packages/requests/models.py", line 1026, in raise_for_status
    raise HTTPError(http_error_msg, response=self)
requests.exceptions.HTTPError: 503 Server Error: Service Temporarily Unavailable for url: https://api.genai.army.mil/user//get-token-with-api-key
2025-09-29 18:15:30 ERROR    __main__ :: [MAIN pid=66871 proc=MainProcess] Worker crashed: 503 Server Error: Service Temporarily Unavailable for url: https://api.genai.army.mil/user//get-token-with-api-key
2025-09-29 18:15:30 ERROR    asksageclient.client :: Http Error:
Traceback (most recent call last):
  File "/home/jupyter-zszewczyk/.conda/envs/watson/lib/python3.12/site-packages/asksageclient/client.py", line 46, in _request
    response.raise_for_status()
  File "/home/jupyter-zszewczyk/.conda/envs/watson/lib/python3.12/site-packages/requests/models.py", line 1026, in raise_for_status
    raise HTTPError(http_error_msg, response=self)
requests.exceptions.HTTPError: 503 Server Error: Service Temporarily Unavailable for url: https://api.genai.army.mil/user//get-token-with-api-key
2025-09-29 18:15:30 ERROR    __main__ :: [MAIN pid=66871 proc=MainProcess] Worker crashed: 503 Server Error: Service Temporarily Unavailable for url: https://api.genai.army.mil/user//get-token-with-api-key
2025-09-29 18:15:30 ERROR    asksageclient.client :: Http Error:
Traceback (most recent call last):
  File "/home/jupyter-zszewczyk/.conda/envs/watson/lib/python3.12/site-packages/asksageclient/client.py", line 46, in _request
    response.raise_for_status()
  File "/home/jupyter-zszewczyk/.conda/envs/watson/lib/python3.12/site-packages/requests/models.py", line 1026, in raise_for_status
    raise HTTPError(http_error_msg, response=self)
requests.exceptions.HTTPError: 503 Server Error: Service Temporarily Unavailable for url: https://api.genai.army.mil/user//get-token-with-api-key
2025-09-29 18:15:30 ERROR    __main__ :: [MAIN pid=66871 proc=MainProcess] Worker crashed: 503 Server Error: Service Temporarily Unavailable for url: https://api.genai.army.mil/user//get-token-with-api-key
2025-09-29 18:15:30 ERROR    asksageclient.client :: Http Error:
Traceback (most recent call last):
  File "/home/jupyter-zszewczyk/.conda/envs/watson/lib/python3.12/site-packages/asksageclient/client.py", line 46, in _request
    response.raise_for_status()
  File "/home/jupyter-zszewczyk/.conda/envs/watson/lib/python3.12/site-packages/requests/models.py", line 1026, in raise_for_status
    raise HTTPError(http_error_msg, response=self)
requests.exceptions.HTTPError: 503 Server Error: Service Temporarily Unavailable for url: https://api.genai.army.mil/user//get-token-with-api-key
2025-09-29 18:15:30 ERROR    __main__ :: [MAIN pid=66871 proc=MainProcess] Worker crashed: 503 Server Error: Service Temporarily Unavailable for url: https://api.genai.army.mil/user//get-token-with-api-key
2025-09-29 18:15:31 ERROR    asksageclient.client :: Http Error:
Traceback (most recent call last):
  File "/home/jupyter-zszewczyk/.conda/envs/watson/lib/python3.12/site-packages/asksageclient/client.py", line 46, in _request
    response.raise_for_status()
  File "/home/jupyter-zszewczyk/.conda/envs/watson/lib/python3.12/site-packages/requests/models.py", line 1026, in raise_for_status
    raise HTTPError(http_error_msg, response=self)
requests.exceptions.HTTPError: 503 Server Error: Service Temporarily Unavailable for url: https://api.genai.army.mil/user//get-token-with-api-key
2025-09-29 18:15:31 ERROR    __main__ :: [MAIN pid=66871 proc=MainProcess] Worker crashed: 503 Server Error: Service Temporarily Unavailable for url: https://api.genai.army.mil/user//get-token-with-api-key
2025-09-29 18:15:31 ERROR    asksageclient.client :: Http Error:
Traceback (most recent call last):
  File "/home/jupyter-zszewczyk/.conda/envs/watson/lib/python3.12/site-packages/asksageclient/client.py", line 46, in _request
    response.raise_for_status()
  File "/home/jupyter-zszewczyk/.conda/envs/watson/lib/python3.12/site-packages/requests/models.py", line 1026, in raise_for_status
    raise HTTPError(http_error_msg, response=self)
requests.exceptions.HTTPError: 503 Server Error: Service Temporarily Unavailable for url: https://api.genai.army.mil/user//get-token-with-api-key
2025-09-29 18:15:31 ERROR    __main__ :: [MAIN pid=66871 proc=MainProcess] Worker crashed: 503 Server Error: Service Temporarily Unavailable for url: https://api.genai.army.mil/user//get-token-with-api-key
2025-09-29 18:15:31 ERROR    asksageclient.client :: Http Error:
Traceback (most recent call last):
  File "/home/jupyter-zszewczyk/.conda/envs/watson/lib/python3.12/site-packages/asksageclient/client.py", line 46, in _request
    response.raise_for_status()
  File "/home/jupyter-zszewczyk/.conda/envs/watson/lib/python3.12/site-packages/requests/models.py", line 1026, in raise_for_status
    raise HTTPError(http_error_msg, response=self)
requests.exceptions.HTTPError: 503 Server Error: Service Temporarily Unavailable for url: https://api.genai.army.mil/user//get-token-with-api-key
2025-09-29 18:15:31 ERROR    __main__ :: [MAIN pid=66871 proc=MainProcess] Worker crashed: 503 Server Error: Service Temporarily Unavailable for url: https://api.genai.army.mil/user//get-token-with-api-key
2025-09-29 18:15:31 ERROR    asksageclient.client :: Http Error:
Traceback (most recent call last):
  File "/home/jupyter-zszewczyk/.conda/envs/watson/lib/python3.12/site-packages/asksageclient/client.py", line 46, in _request
    response.raise_for_status()
  File "/home/jupyter-zszewczyk/.conda/envs/watson/lib/python3.12/site-packages/requests/models.py", line 1026, in raise_for_status
    raise HTTPError(http_error_msg, response=self)
requests.exceptions.HTTPError: 503 Server Error: Service Temporarily Unavailable for url: https://api.genai.army.mil/user//get-token-with-api-key
2025-09-29 18:15:31 ERROR    __main__ :: [MAIN pid=66871 proc=MainProcess] Worker crashed: 503 Server Error: Service Temporarily Unavailable for url: https://api.genai.army.mil/user//get-token-with-api-key
2025-09-29 18:15:31 ERROR    asksageclient.client :: Http Error:
Traceback (most recent call last):
  File "/home/jupyter-zszewczyk/.conda/envs/watson/lib/python3.12/site-packages/asksageclient/client.py", line 46, in _request
    response.raise_for_status()
  File "/home/jupyter-zszewczyk/.conda/envs/watson/lib/python3.12/site-packages/requests/models.py", line 1026, in raise_for_status
    raise HTTPError(http_error_msg, response=self)
requests.exceptions.HTTPError: 503 Server Error: Service Temporarily Unavailable for url: https://api.genai.army.mil/user//get-token-with-api-key
2025-09-29 18:15:31 ERROR    __main__ :: [MAIN pid=66871 proc=MainProcess] Worker crashed: 503 Server Error: Service Temporarily Unavailable for url: https://api.genai.army.mil/user//get-token-with-api-key
2025-09-29 18:15:31 ERROR    asksageclient.client :: Http Error:
Traceback (most recent call last):
  File "/home/jupyter-zszewczyk/.conda/envs/watson/lib/python3.12/site-packages/asksageclient/client.py", line 46, in _request
    response.raise_for_status()
  File "/home/jupyter-zszewczyk/.conda/envs/watson/lib/python3.12/site-packages/requests/models.py", line 1026, in raise_for_status
    raise HTTPError(http_error_msg, response=self)
requests.exceptions.HTTPError: 503 Server Error: Service Temporarily Unavailable for url: https://api.genai.army.mil/user//get-token-with-api-key
2025-09-29 18:15:31 ERROR    __main__ :: [MAIN pid=66871 proc=MainProcess] Worker crashed: 503 Server Error: Service Temporarily Unavailable for url: https://api.genai.army.mil/user//get-token-with-api-key
2025-09-29 18:15:31 ERROR    asksageclient.client :: Http Error:
Traceback (most recent call last):
  File "/home/jupyter-zszewczyk/.conda/envs/watson/lib/python3.12/site-packages/asksageclient/client.py", line 46, in _request
    response.raise_for_status()
  File "/home/jupyter-zszewczyk/.conda/envs/watson/lib/python3.12/site-packages/requests/models.py", line 1026, in raise_for_status
    raise HTTPError(http_error_msg, response=self)
requests.exceptions.HTTPError: 503 Server Error: Service Temporarily Unavailable for url: https://api.genai.army.mil/user//get-token-with-api-key
2025-09-29 18:15:31 ERROR    __main__ :: [MAIN pid=66871 proc=MainProcess] Worker crashed: 503 Server Error: Service Temporarily Unavailable for url: https://api.genai.army.mil/user//get-token-with-api-key
2025-09-29 18:15:31 ERROR    asksageclient.client :: Http Error:
Traceback (most recent call last):
  File "/home/jupyter-zszewczyk/.conda/envs/watson/lib/python3.12/site-packages/asksageclient/client.py", line 46, in _request
    response.raise_for_status()
  File "/home/jupyter-zszewczyk/.conda/envs/watson/lib/python3.12/site-packages/requests/models.py", line 1026, in raise_for_status
    raise HTTPError(http_error_msg, response=self)
requests.exceptions.HTTPError: 503 Server Error: Service Temporarily Unavailable for url: https://api.genai.army.mil/user//get-token-with-api-key
2025-09-29 18:15:31 ERROR    __main__ :: [MAIN pid=66871 proc=MainProcess] Worker crashed: 503 Server Error: Service Temporarily Unavailable for url: https://api.genai.army.mil/user//get-token-with-api-key
2025-09-29 18:15:31 ERROR    asksageclient.client :: Http Error:
Traceback (most recent call last):
  File "/home/jupyter-zszewczyk/.conda/envs/watson/lib/python3.12/site-packages/asksageclient/client.py", line 46, in _request
    response.raise_for_status()
  File "/home/jupyter-zszewczyk/.conda/envs/watson/lib/python3.12/site-packages/requests/models.py", line 1026, in raise_for_status
    raise HTTPError(http_error_msg, response=self)
requests.exceptions.HTTPError: 503 Server Error: Service Temporarily Unavailable for url: https://api.genai.army.mil/user//get-token-with-api-key
2025-09-29 18:15:31 ERROR    __main__ :: [MAIN pid=66871 proc=MainProcess] Worker crashed: 503 Server Error: Service Temporarily Unavailable for url: https://api.genai.army.mil/user//get-token-with-api-key
2025-09-29 18:15:31 ERROR    asksageclient.client :: Http Error:
Traceback (most recent call last):
  File "/home/jupyter-zszewczyk/.conda/envs/watson/lib/python3.12/site-packages/asksageclient/client.py", line 46, in _request
    response.raise_for_status()
  File "/home/jupyter-zszewczyk/.conda/envs/watson/lib/python3.12/site-packages/requests/models.py", line 1026, in raise_for_status
    raise HTTPError(http_error_msg, response=self)
requests.exceptions.HTTPError: 503 Server Error: Service Temporarily Unavailable for url: https://api.genai.army.mil/user//get-token-with-api-key
2025-09-29 18:15:31 ERROR    __main__ :: [MAIN pid=66871 proc=MainProcess] Worker crashed: 503 Server Error: Service Temporarily Unavailable for url: https://api.genai.army.mil/user//get-token-with-api-key
2025-09-29 18:15:31 ERROR    asksageclient.client :: Http Error:
Traceback (most recent call last):
  File "/home/jupyter-zszewczyk/.conda/envs/watson/lib/python3.12/site-packages/asksageclient/client.py", line 46, in _request
    response.raise_for_status()
  File "/home/jupyter-zszewczyk/.conda/envs/watson/lib/python3.12/site-packages/requests/models.py", line 1026, in raise_for_status
    raise HTTPError(http_error_msg, response=self)
requests.exceptions.HTTPError: 503 Server Error: Service Temporarily Unavailable for url: https://api.genai.army.mil/user//get-token-with-api-key
2025-09-29 18:15:31 ERROR    __main__ :: [MAIN pid=66871 proc=MainProcess] Worker crashed: 503 Server Error: Service Temporarily Unavailable for url: https://api.genai.army.mil/user//get-token-with-api-key
2025-09-29 18:15:32 ERROR    asksageclient.client :: Http Error:
Traceback (most recent call last):
  File "/home/jupyter-zszewczyk/.conda/envs/watson/lib/python3.12/site-packages/asksageclient/client.py", line 46, in _request
    response.raise_for_status()
  File "/home/jupyter-zszewczyk/.conda/envs/watson/lib/python3.12/site-packages/requests/models.py", line 1026, in raise_for_status
    raise HTTPError(http_error_msg, response=self)
requests.exceptions.HTTPError: 503 Server Error: Service Temporarily Unavailable for url: https://api.genai.army.mil/user//get-token-with-api-key
2025-09-29 18:15:32 ERROR    __main__ :: [MAIN pid=66871 proc=MainProcess] Worker crashed: 503 Server Error: Service Temporarily Unavailable for url: https://api.genai.army.mil/user//get-token-with-api-key
2025-09-29 18:15:32 ERROR    asksageclient.client :: Http Error:
Traceback (most recent call last):
  File "/home/jupyter-zszewczyk/.conda/envs/watson/lib/python3.12/site-packages/asksageclient/client.py", line 46, in _request
    response.raise_for_status()
  File "/home/jupyter-zszewczyk/.conda/envs/watson/lib/python3.12/site-packages/requests/models.py", line 1026, in raise_for_status
    raise HTTPError(http_error_msg, response=self)
requests.exceptions.HTTPError: 503 Server Error: Service Temporarily Unavailable for url: https://api.genai.army.mil/user//get-token-with-api-key
2025-09-29 18:15:32 ERROR    __main__ :: [MAIN pid=66871 proc=MainProcess] Worker crashed: 503 Server Error: Service Temporarily Unavailable for url: https://api.genai.army.mil/user//get-token-with-api-key
2025-09-29 18:15:32 ERROR    asksageclient.client :: Http Error:
Traceback (most recent call last):
  File "/home/jupyter-zszewczyk/.conda/envs/watson/lib/python3.12/site-packages/asksageclient/client.py", line 46, in _request
    response.raise_for_status()
  File "/home/jupyter-zszewczyk/.conda/envs/watson/lib/python3.12/site-packages/requests/models.py", line 1026, in raise_for_status
    raise HTTPError(http_error_msg, response=self)
requests.exceptions.HTTPError: 503 Server Error: Service Temporarily Unavailable for url: https://api.genai.army.mil/user//get-token-with-api-key
2025-09-29 18:15:32 ERROR    __main__ :: [MAIN pid=66871 proc=MainProcess] Worker crashed: 503 Server Error: Service Temporarily Unavailable for url: https://api.genai.army.mil/user//get-token-with-api-key
2025-09-29 18:15:32 ERROR    asksageclient.client :: Http Error:
Traceback (most recent call last):
  File "/home/jupyter-zszewczyk/.conda/envs/watson/lib/python3.12/site-packages/asksageclient/client.py", line 46, in _request
    response.raise_for_status()
  File "/home/jupyter-zszewczyk/.conda/envs/watson/lib/python3.12/site-packages/requests/models.py", line 1026, in raise_for_status
    raise HTTPError(http_error_msg, response=self)
requests.exceptions.HTTPError: 503 Server Error: Service Temporarily Unavailable for url: https://api.genai.army.mil/user//get-token-with-api-key
2025-09-29 18:15:32 ERROR    __main__ :: [MAIN pid=66871 proc=MainProcess] Worker crashed: 503 Server Error: Service Temporarily Unavailable for url: https://api.genai.army.mil/user//get-token-with-api-key
2025-09-29 18:15:32 ERROR    asksageclient.client :: Http Error:
Traceback (most recent call last):
  File "/home/jupyter-zszewczyk/.conda/envs/watson/lib/python3.12/site-packages/asksageclient/client.py", line 46, in _request
    response.raise_for_status()
  File "/home/jupyter-zszewczyk/.conda/envs/watson/lib/python3.12/site-packages/requests/models.py", line 1026, in raise_for_status
    raise HTTPError(http_error_msg, response=self)
requests.exceptions.HTTPError: 503 Server Error: Service Temporarily Unavailable for url: https://api.genai.army.mil/user//get-token-with-api-key
2025-09-29 18:15:32 ERROR    __main__ :: [MAIN pid=66871 proc=MainProcess] Worker crashed: 503 Server Error: Service Temporarily Unavailable for url: https://api.genai.army.mil/user//get-token-with-api-key
2025-09-29 18:15:32 ERROR    asksageclient.client :: Http Error:
Traceback (most recent call last):
  File "/home/jupyter-zszewczyk/.conda/envs/watson/lib/python3.12/site-packages/asksageclient/client.py", line 46, in _request
    response.raise_for_status()
  File "/home/jupyter-zszewczyk/.conda/envs/watson/lib/python3.12/site-packages/requests/models.py", line 1026, in raise_for_status
    raise HTTPError(http_error_msg, response=self)
requests.exceptions.HTTPError: 503 Server Error: Service Temporarily Unavailable for url: https://api.genai.army.mil/user//get-token-with-api-key
2025-09-29 18:15:32 ERROR    __main__ :: [MAIN pid=66871 proc=MainProcess] Worker crashed: 503 Server Error: Service Temporarily Unavailable for url: https://api.genai.army.mil/user//get-token-with-api-key
2025-09-29 18:15:32 ERROR    asksageclient.client :: Http Error:
Traceback (most recent call last):
  File "/home/jupyter-zszewczyk/.conda/envs/watson/lib/python3.12/site-packages/asksageclient/client.py", line 46, in _request
    response.raise_for_status()
  File "/home/jupyter-zszewczyk/.conda/envs/watson/lib/python3.12/site-packages/requests/models.py", line 1026, in raise_for_status
    raise HTTPError(http_error_msg, response=self)
requests.exceptions.HTTPError: 503 Server Error: Service Temporarily Unavailable for url: https://api.genai.army.mil/user//get-token-with-api-key
2025-09-29 18:15:32 ERROR    __main__ :: [MAIN pid=66871 proc=MainProcess] Worker crashed: 503 Server Error: Service Temporarily Unavailable for url: https://api.genai.army.mil/user//get-token-with-api-key
2025-09-29 18:15:32 ERROR    asksageclient.client :: Http Error:
Traceback (most recent call last):
  File "/home/jupyter-zszewczyk/.conda/envs/watson/lib/python3.12/site-packages/asksageclient/client.py", line 46, in _request
    response.raise_for_status()
  File "/home/jupyter-zszewczyk/.conda/envs/watson/lib/python3.12/site-packages/requests/models.py", line 1026, in raise_for_status
    raise HTTPError(http_error_msg, response=self)
requests.exceptions.HTTPError: 503 Server Error: Service Temporarily Unavailable for url: https://api.genai.army.mil/user//get-token-with-api-key
2025-09-29 18:15:32 ERROR    __main__ :: [MAIN pid=66871 proc=MainProcess] Worker crashed: 503 Server Error: Service Temporarily Unavailable for url: https://api.genai.army.mil/user//get-token-with-api-key
2025-09-29 18:15:32 ERROR    asksageclient.client :: Http Error:
Traceback (most recent call last):
  File "/home/jupyter-zszewczyk/.conda/envs/watson/lib/python3.12/site-packages/asksageclient/client.py", line 46, in _request
    response.raise_for_status()
  File "/home/jupyter-zszewczyk/.conda/envs/watson/lib/python3.12/site-packages/requests/models.py", line 1026, in raise_for_status
    raise HTTPError(http_error_msg, response=self)
requests.exceptions.HTTPError: 503 Server Error: Service Temporarily Unavailable for url: https://api.genai.army.mil/user//get-token-with-api-key
2025-09-29 18:15:32 ERROR    __main__ :: [MAIN pid=66871 proc=MainProcess] Worker crashed: 503 Server Error: Service Temporarily Unavailable for url: https://api.genai.army.mil/user//get-token-with-api-key
2025-09-29 18:15:32 ERROR    asksageclient.client :: Http Error:
Traceback (most recent call last):
  File "/home/jupyter-zszewczyk/.conda/envs/watson/lib/python3.12/site-packages/asksageclient/client.py", line 46, in _request
    response.raise_for_status()
  File "/home/jupyter-zszewczyk/.conda/envs/watson/lib/python3.12/site-packages/requests/models.py", line 1026, in raise_for_status
    raise HTTPError(http_error_msg, response=self)
requests.exceptions.HTTPError: 503 Server Error: Service Temporarily Unavailable for url: https://api.genai.army.mil/user//get-token-with-api-key
2025-09-29 18:15:32 ERROR    __main__ :: [MAIN pid=66871 proc=MainProcess] Worker crashed: 503 Server Error: Service Temporarily Unavailable for url: https://api.genai.army.mil/user//get-token-with-api-key
2025-09-29 18:15:33 ERROR    asksageclient.client :: Http Error:
Traceback (most recent call last):
  File "/home/jupyter-zszewczyk/.conda/envs/watson/lib/python3.12/site-packages/asksageclient/client.py", line 46, in _request
    response.raise_for_status()
  File "/home/jupyter-zszewczyk/.conda/envs/watson/lib/python3.12/site-packages/requests/models.py", line 1026, in raise_for_status
    raise HTTPError(http_error_msg, response=self)
requests.exceptions.HTTPError: 503 Server Error: Service Temporarily Unavailable for url: https://api.genai.army.mil/user//get-token-with-api-key
2025-09-29 18:15:33 ERROR    __main__ :: [MAIN pid=66871 proc=MainProcess] Worker crashed: 503 Server Error: Service Temporarily Unavailable for url: https://api.genai.army.mil/user//get-token-with-api-key
2025-09-29 18:15:33 ERROR    asksageclient.client :: Http Error:
Traceback (most recent call last):
  File "/home/jupyter-zszewczyk/.conda/envs/watson/lib/python3.12/site-packages/asksageclient/client.py", line 46, in _request
    response.raise_for_status()
  File "/home/jupyter-zszewczyk/.conda/envs/watson/lib/python3.12/site-packages/requests/models.py", line 1026, in raise_for_status
    raise HTTPError(http_error_msg, response=self)
requests.exceptions.HTTPError: 503 Server Error: Service Temporarily Unavailable for url: https://api.genai.army.mil/user//get-token-with-api-key
2025-09-29 18:15:33 ERROR    __main__ :: [MAIN pid=66871 proc=MainProcess] Worker crashed: 503 Server Error: Service Temporarily Unavailable for url: https://api.genai.army.mil/user//get-token-with-api-key
2025-09-29 18:15:33 ERROR    asksageclient.client :: Http Error:
Traceback (most recent call last):
  File "/home/jupyter-zszewczyk/.conda/envs/watson/lib/python3.12/site-packages/asksageclient/client.py", line 46, in _request
    response.raise_for_status()
  File "/home/jupyter-zszewczyk/.conda/envs/watson/lib/python3.12/site-packages/requests/models.py", line 1026, in raise_for_status
    raise HTTPError(http_error_msg, response=self)
requests.exceptions.HTTPError: 503 Server Error: Service Temporarily Unavailable for url: https://api.genai.army.mil/user//get-token-with-api-key
2025-09-29 18:15:33 ERROR    __main__ :: [MAIN pid=66871 proc=MainProcess] Worker crashed: 503 Server Error: Service Temporarily Unavailable for url: https://api.genai.army.mil/user//get-token-with-api-key
2025-09-29 18:15:33 ERROR    asksageclient.client :: Http Error:
Traceback (most recent call last):
  File "/home/jupyter-zszewczyk/.conda/envs/watson/lib/python3.12/site-packages/asksageclient/client.py", line 46, in _request
    response.raise_for_status()
  File "/home/jupyter-zszewczyk/.conda/envs/watson/lib/python3.12/site-packages/requests/models.py", line 1026, in raise_for_status
    raise HTTPError(http_error_msg, response=self)
requests.exceptions.HTTPError: 503 Server Error: Service Temporarily Unavailable for url: https://api.genai.army.mil/user//get-token-with-api-key
2025-09-29 18:15:33 ERROR    __main__ :: [MAIN pid=66871 proc=MainProcess] Worker crashed: 503 Server Error: Service Temporarily Unavailable for url: https://api.genai.army.mil/user//get-token-with-api-key
2025-09-29 18:15:33 ERROR    asksageclient.client :: Http Error:
Traceback (most recent call last):
  File "/home/jupyter-zszewczyk/.conda/envs/watson/lib/python3.12/site-packages/asksageclient/client.py", line 46, in _request
    response.raise_for_status()
  File "/home/jupyter-zszewczyk/.conda/envs/watson/lib/python3.12/site-packages/requests/models.py", line 1026, in raise_for_status
    raise HTTPError(http_error_msg, response=self)
requests.exceptions.HTTPError: 503 Server Error: Service Temporarily Unavailable for url: https://api.genai.army.mil/user//get-token-with-api-key
2025-09-29 18:15:33 ERROR    __main__ :: [MAIN pid=66871 proc=MainProcess] Worker crashed: 503 Server Error: Service Temporarily Unavailable for url: https://api.genai.army.mil/user//get-token-with-api-key
2025-09-29 18:15:33 ERROR    asksageclient.client :: Http Error:
Traceback (most recent call last):
  File "/home/jupyter-zszewczyk/.conda/envs/watson/lib/python3.12/site-packages/asksageclient/client.py", line 46, in _request
    response.raise_for_status()
  File "/home/jupyter-zszewczyk/.conda/envs/watson/lib/python3.12/site-packages/requests/models.py", line 1026, in raise_for_status
    raise HTTPError(http_error_msg, response=self)
requests.exceptions.HTTPError: 503 Server Error: Service Temporarily Unavailable for url: https://api.genai.army.mil/user//get-token-with-api-key
2025-09-29 18:15:33 ERROR    __main__ :: [MAIN pid=66871 proc=MainProcess] Worker crashed: 503 Server Error: Service Temporarily Unavailable for url: https://api.genai.army.mil/user//get-token-with-api-key
2025-09-29 18:15:33 ERROR    asksageclient.client :: Http Error:
Traceback (most recent call last):
  File "/home/jupyter-zszewczyk/.conda/envs/watson/lib/python3.12/site-packages/asksageclient/client.py", line 46, in _request
    response.raise_for_status()
  File "/home/jupyter-zszewczyk/.conda/envs/watson/lib/python3.12/site-packages/requests/models.py", line 1026, in raise_for_status
    raise HTTPError(http_error_msg, response=self)
requests.exceptions.HTTPError: 503 Server Error: Service Temporarily Unavailable for url: https://api.genai.army.mil/user//get-token-with-api-key
2025-09-29 18:15:33 ERROR    __main__ :: [MAIN pid=66871 proc=MainProcess] Worker crashed: 503 Server Error: Service Temporarily Unavailable for url: https://api.genai.army.mil/user//get-token-with-api-key
2025-09-29 18:15:33 ERROR    asksageclient.client :: Http Error:
Traceback (most recent call last):
  File "/home/jupyter-zszewczyk/.conda/envs/watson/lib/python3.12/site-packages/asksageclient/client.py", line 46, in _request
    response.raise_for_status()
  File "/home/jupyter-zszewczyk/.conda/envs/watson/lib/python3.12/site-packages/requests/models.py", line 1026, in raise_for_status
    raise HTTPError(http_error_msg, response=self)
requests.exceptions.HTTPError: 503 Server Error: Service Temporarily Unavailable for url: https://api.genai.army.mil/user//get-token-with-api-key
2025-09-29 18:15:33 ERROR    __main__ :: [MAIN pid=66871 proc=MainProcess] Worker crashed: 503 Server Error: Service Temporarily Unavailable for url: https://api.genai.army.mil/user//get-token-with-api-key
2025-09-29 18:15:33 ERROR    asksageclient.client :: Http Error:
Traceback (most recent call last):
  File "/home/jupyter-zszewczyk/.conda/envs/watson/lib/python3.12/site-packages/asksageclient/client.py", line 46, in _request
    response.raise_for_status()
  File "/home/jupyter-zszewczyk/.conda/envs/watson/lib/python3.12/site-packages/requests/models.py", line 1026, in raise_for_status
    raise HTTPError(http_error_msg, response=self)
requests.exceptions.HTTPError: 503 Server Error: Service Temporarily Unavailable for url: https://api.genai.army.mil/user//get-token-with-api-key
2025-09-29 18:15:33 ERROR    __main__ :: [MAIN pid=66871 proc=MainProcess] Worker crashed: 503 Server Error: Service Temporarily Unavailable for url: https://api.genai.army.mil/user//get-token-with-api-key
2025-09-29 18:15:33 ERROR    asksageclient.client :: Http Error:
Traceback (most recent call last):
  File "/home/jupyter-zszewczyk/.conda/envs/watson/lib/python3.12/site-packages/asksageclient/client.py", line 46, in _request
    response.raise_for_status()
  File "/home/jupyter-zszewczyk/.conda/envs/watson/lib/python3.12/site-packages/requests/models.py", line 1026, in raise_for_status
    raise HTTPError(http_error_msg, response=self)
requests.exceptions.HTTPError: 503 Server Error: Service Temporarily Unavailable for url: https://api.genai.army.mil/user//get-token-with-api-key
2025-09-29 18:15:33 ERROR    __main__ :: [MAIN pid=66871 proc=MainProcess] Worker crashed: 503 Server Error: Service Temporarily Unavailable for url: https://api.genai.army.mil/user//get-token-with-api-key
2025-09-29 18:15:33 ERROR    asksageclient.client :: Http Error:
Traceback (most recent call last):
  File "/home/jupyter-zszewczyk/.conda/envs/watson/lib/python3.12/site-packages/asksageclient/client.py", line 46, in _request
    response.raise_for_status()
  File "/home/jupyter-zszewczyk/.conda/envs/watson/lib/python3.12/site-packages/requests/models.py", line 1026, in raise_for_status
    raise HTTPError(http_error_msg, response=self)
requests.exceptions.HTTPError: 503 Server Error: Service Temporarily Unavailable for url: https://api.genai.army.mil/user//get-token-with-api-key
2025-09-29 18:15:33 ERROR    __main__ :: [MAIN pid=66871 proc=MainProcess] Worker crashed: 503 Server Error: Service Temporarily Unavailable for url: https://api.genai.army.mil/user//get-token-with-api-key
2025-09-29 18:15:33 ERROR    asksageclient.client :: Http Error:
Traceback (most recent call last):
  File "/home/jupyter-zszewczyk/.conda/envs/watson/lib/python3.12/site-packages/asksageclient/client.py", line 46, in _request
    response.raise_for_status()
  File "/home/jupyter-zszewczyk/.conda/envs/watson/lib/python3.12/site-packages/requests/models.py", line 1026, in raise_for_status
    raise HTTPError(http_error_msg, response=self)
requests.exceptions.HTTPError: 503 Server Error: Service Temporarily Unavailable for url: https://api.genai.army.mil/user//get-token-with-api-key
2025-09-29 18:15:33 ERROR    __main__ :: [MAIN pid=66871 proc=MainProcess] Worker crashed: 503 Server Error: Service Temporarily Unavailable for url: https://api.genai.army.mil/user//get-token-with-api-key
2025-09-29 18:15:34 ERROR    asksageclient.client :: Http Error:
Traceback (most recent call last):
  File "/home/jupyter-zszewczyk/.conda/envs/watson/lib/python3.12/site-packages/asksageclient/client.py", line 46, in _request
    response.raise_for_status()
  File "/home/jupyter-zszewczyk/.conda/envs/watson/lib/python3.12/site-packages/requests/models.py", line 1026, in raise_for_status
    raise HTTPError(http_error_msg, response=self)
requests.exceptions.HTTPError: 503 Server Error: Service Temporarily Unavailable for url: https://api.genai.army.mil/user//get-token-with-api-key
2025-09-29 18:15:34 ERROR    __main__ :: [MAIN pid=66871 proc=MainProcess] Worker crashed: 503 Server Error: Service Temporarily Unavailable for url: https://api.genai.army.mil/user//get-token-with-api-key
2025-09-29 18:15:34 ERROR    asksageclient.client :: Http Error:
Traceback (most recent call last):
  File "/home/jupyter-zszewczyk/.conda/envs/watson/lib/python3.12/site-packages/asksageclient/client.py", line 46, in _request
    response.raise_for_status()
  File "/home/jupyter-zszewczyk/.conda/envs/watson/lib/python3.12/site-packages/requests/models.py", line 1026, in raise_for_status
    raise HTTPError(http_error_msg, response=self)
requests.exceptions.HTTPError: 503 Server Error: Service Temporarily Unavailable for url: https://api.genai.army.mil/user//get-token-with-api-key
2025-09-29 18:15:34 ERROR    __main__ :: [MAIN pid=66871 proc=MainProcess] Worker crashed: 503 Server Error: Service Temporarily Unavailable for url: https://api.genai.army.mil/user//get-token-with-api-key
2025-09-29 18:15:34 ERROR    asksageclient.client :: Http Error:
Traceback (most recent call last):
  File "/home/jupyter-zszewczyk/.conda/envs/watson/lib/python3.12/site-packages/asksageclient/client.py", line 46, in _request
    response.raise_for_status()
  File "/home/jupyter-zszewczyk/.conda/envs/watson/lib/python3.12/site-packages/requests/models.py", line 1026, in raise_for_status
    raise HTTPError(http_error_msg, response=self)
requests.exceptions.HTTPError: 503 Server Error: Service Temporarily Unavailable for url: https://api.genai.army.mil/user//get-token-with-api-key
2025-09-29 18:15:34 ERROR    __main__ :: [MAIN pid=66871 proc=MainProcess] Worker crashed: 503 Server Error: Service Temporarily Unavailable for url: https://api.genai.army.mil/user//get-token-with-api-key
2025-09-29 18:15:34 ERROR    asksageclient.client :: Http Error:
Traceback (most recent call last):
  File "/home/jupyter-zszewczyk/.conda/envs/watson/lib/python3.12/site-packages/asksageclient/client.py", line 46, in _request
    response.raise_for_status()
  File "/home/jupyter-zszewczyk/.conda/envs/watson/lib/python3.12/site-packages/requests/models.py", line 1026, in raise_for_status
    raise HTTPError(http_error_msg, response=self)
requests.exceptions.HTTPError: 503 Server Error: Service Temporarily Unavailable for url: https://api.genai.army.mil/user//get-token-with-api-key
2025-09-29 18:15:34 ERROR    __main__ :: [MAIN pid=66871 proc=MainProcess] Worker crashed: 503 Server Error: Service Temporarily Unavailable for url: https://api.genai.army.mil/user//get-token-with-api-key
2025-09-29 18:15:34 ERROR    asksageclient.client :: Http Error:
Traceback (most recent call last):
  File "/home/jupyter-zszewczyk/.conda/envs/watson/lib/python3.12/site-packages/asksageclient/client.py", line 46, in _request
    response.raise_for_status()
  File "/home/jupyter-zszewczyk/.conda/envs/watson/lib/python3.12/site-packages/requests/models.py", line 1026, in raise_for_status
    raise HTTPError(http_error_msg, response=self)
requests.exceptions.HTTPError: 503 Server Error: Service Temporarily Unavailable for url: https://api.genai.army.mil/user//get-token-with-api-key
2025-09-29 18:15:34 ERROR    __main__ :: [MAIN pid=66871 proc=MainProcess] Worker crashed: 503 Server Error: Service Temporarily Unavailable for url: https://api.genai.army.mil/user//get-token-with-api-key
2025-09-29 18:15:34 ERROR    asksageclient.client :: Http Error:
Traceback (most recent call last):
  File "/home/jupyter-zszewczyk/.conda/envs/watson/lib/python3.12/site-packages/asksageclient/client.py", line 46, in _request
    response.raise_for_status()
  File "/home/jupyter-zszewczyk/.conda/envs/watson/lib/python3.12/site-packages/requests/models.py", line 1026, in raise_for_status
    raise HTTPError(http_error_msg, response=self)
requests.exceptions.HTTPError: 503 Server Error: Service Temporarily Unavailable for url: https://api.genai.army.mil/user//get-token-with-api-key
2025-09-29 18:15:34 ERROR    __main__ :: [MAIN pid=66871 proc=MainProcess] Worker crashed: 503 Server Error: Service Temporarily Unavailable for url: https://api.genai.army.mil/user//get-token-with-api-key
2025-09-29 18:15:34 ERROR    asksageclient.client :: Http Error:
Traceback (most recent call last):
  File "/home/jupyter-zszewczyk/.conda/envs/watson/lib/python3.12/site-packages/asksageclient/client.py", line 46, in _request
    response.raise_for_status()
  File "/home/jupyter-zszewczyk/.conda/envs/watson/lib/python3.12/site-packages/requests/models.py", line 1026, in raise_for_status
    raise HTTPError(http_error_msg, response=self)
requests.exceptions.HTTPError: 503 Server Error: Service Temporarily Unavailable for url: https://api.genai.army.mil/user//get-token-with-api-key
2025-09-29 18:15:34 ERROR    __main__ :: [MAIN pid=66871 proc=MainProcess] Worker crashed: 503 Server Error: Service Temporarily Unavailable for url: https://api.genai.army.mil/user//get-token-with-api-key
2025-09-29 18:15:34 ERROR    asksageclient.client :: Http Error:
Traceback (most recent call last):
  File "/home/jupyter-zszewczyk/.conda/envs/watson/lib/python3.12/site-packages/asksageclient/client.py", line 46, in _request
    response.raise_for_status()
  File "/home/jupyter-zszewczyk/.conda/envs/watson/lib/python3.12/site-packages/requests/models.py", line 1026, in raise_for_status
    raise HTTPError(http_error_msg, response=self)
requests.exceptions.HTTPError: 503 Server Error: Service Temporarily Unavailable for url: https://api.genai.army.mil/user//get-token-with-api-key
2025-09-29 18:15:34 ERROR    __main__ :: [MAIN pid=66871 proc=MainProcess] Worker crashed: 503 Server Error: Service Temporarily Unavailable for url: https://api.genai.army.mil/user//get-token-with-api-key
2025-09-29 18:15:34 ERROR    asksageclient.client :: Http Error:
Traceback (most recent call last):
  File "/home/jupyter-zszewczyk/.conda/envs/watson/lib/python3.12/site-packages/asksageclient/client.py", line 46, in _request
    response.raise_for_status()
  File "/home/jupyter-zszewczyk/.conda/envs/watson/lib/python3.12/site-packages/requests/models.py", line 1026, in raise_for_status
    raise HTTPError(http_error_msg, response=self)
requests.exceptions.HTTPError: 503 Server Error: Service Temporarily Unavailable for url: https://api.genai.army.mil/user//get-token-with-api-key
2025-09-29 18:15:34 ERROR    asksageclient.client :: Http Error:
Traceback (most recent call last):
  File "/home/jupyter-zszewczyk/.conda/envs/watson/lib/python3.12/site-packages/asksageclient/client.py", line 46, in _request
    response.raise_for_status()
  File "/home/jupyter-zszewczyk/.conda/envs/watson/lib/python3.12/site-packages/requests/models.py", line 1026, in raise_for_status
    raise HTTPError(http_error_msg, response=self)
requests.exceptions.HTTPError: 503 Server Error: Service Temporarily Unavailable for url: https://api.genai.army.mil/user//get-token-with-api-key
2025-09-29 18:15:34 ERROR    __main__ :: [MAIN pid=66871 proc=MainProcess] Worker crashed: 503 Server Error: Service Temporarily Unavailable for url: https://api.genai.army.mil/user//get-token-with-api-key
2025-09-29 18:15:34 ERROR    __main__ :: [MAIN pid=66871 proc=MainProcess] Worker crashed: 503 Server Error: Service Temporarily Unavailable for url: https://api.genai.army.mil/user//get-token-with-api-key
2025-09-29 18:15:34 ERROR    asksageclient.client :: Http Error:
Traceback (most recent call last):
  File "/home/jupyter-zszewczyk/.conda/envs/watson/lib/python3.12/site-packages/asksageclient/client.py", line 46, in _request
    response.raise_for_status()
  File "/home/jupyter-zszewczyk/.conda/envs/watson/lib/python3.12/site-packages/requests/models.py", line 1026, in raise_for_status
    raise HTTPError(http_error_msg, response=self)
requests.exceptions.HTTPError: 503 Server Error: Service Temporarily Unavailable for url: https://api.genai.army.mil/user//get-token-with-api-key
2025-09-29 18:15:34 ERROR    asksageclient.client :: Http Error:
Traceback (most recent call last):
  File "/home/jupyter-zszewczyk/.conda/envs/watson/lib/python3.12/site-packages/asksageclient/client.py", line 46, in _request
    response.raise_for_status()
  File "/home/jupyter-zszewczyk/.conda/envs/watson/lib/python3.12/site-packages/requests/models.py", line 1026, in raise_for_status
    raise HTTPError(http_error_msg, response=self)
requests.exceptions.HTTPError: 503 Server Error: Service Temporarily Unavailable for url: https://api.genai.army.mil/user//get-token-with-api-key
2025-09-29 18:15:34 ERROR    __main__ :: [MAIN pid=66871 proc=MainProcess] Worker crashed: 503 Server Error: Service Temporarily Unavailable for url: https://api.genai.army.mil/user//get-token-with-api-key
2025-09-29 18:15:34 ERROR    __main__ :: [MAIN pid=66871 proc=MainProcess] Worker crashed: 503 Server Error: Service Temporarily Unavailable for url: https://api.genai.army.mil/user//get-token-with-api-key
2025-09-29 18:15:35 ERROR    asksageclient.client :: Http Error:
Traceback (most recent call last):
  File "/home/jupyter-zszewczyk/.conda/envs/watson/lib/python3.12/site-packages/asksageclient/client.py", line 46, in _request
    response.raise_for_status()
  File "/home/jupyter-zszewczyk/.conda/envs/watson/lib/python3.12/site-packages/requests/models.py", line 1026, in raise_for_status
    raise HTTPError(http_error_msg, response=self)
requests.exceptions.HTTPError: 503 Server Error: Service Temporarily Unavailable for url: https://api.genai.army.mil/user//get-token-with-api-key
2025-09-29 18:15:35 ERROR    __main__ :: [MAIN pid=66871 proc=MainProcess] Worker crashed: 503 Server Error: Service Temporarily Unavailable for url: https://api.genai.army.mil/user//get-token-with-api-key
2025-09-29 18:15:35 ERROR    asksageclient.client :: Http Error:
Traceback (most recent call last):
  File "/home/jupyter-zszewczyk/.conda/envs/watson/lib/python3.12/site-packages/asksageclient/client.py", line 46, in _request
    response.raise_for_status()
  File "/home/jupyter-zszewczyk/.conda/envs/watson/lib/python3.12/site-packages/requests/models.py", line 1026, in raise_for_status
    raise HTTPError(http_error_msg, response=self)
requests.exceptions.HTTPError: 503 Server Error: Service Temporarily Unavailable for url: https://api.genai.army.mil/user//get-token-with-api-key
2025-09-29 18:15:35 ERROR    __main__ :: [MAIN pid=66871 proc=MainProcess] Worker crashed: 503 Server Error: Service Temporarily Unavailable for url: https://api.genai.army.mil/user//get-token-with-api-key
2025-09-29 18:15:35 ERROR    asksageclient.client :: Http Error:
Traceback (most recent call last):
  File "/home/jupyter-zszewczyk/.conda/envs/watson/lib/python3.12/site-packages/asksageclient/client.py", line 46, in _request
    response.raise_for_status()
  File "/home/jupyter-zszewczyk/.conda/envs/watson/lib/python3.12/site-packages/requests/models.py", line 1026, in raise_for_status
    raise HTTPError(http_error_msg, response=self)
requests.exceptions.HTTPError: 503 Server Error: Service Temporarily Unavailable for url: https://api.genai.army.mil/user//get-token-with-api-key
2025-09-29 18:15:35 ERROR    __main__ :: [MAIN pid=66871 proc=MainProcess] Worker crashed: 503 Server Error: Service Temporarily Unavailable for url: https://api.genai.army.mil/user//get-token-with-api-key
2025-09-29 18:15:35 ERROR    asksageclient.client :: Http Error:
Traceback (most recent call last):
  File "/home/jupyter-zszewczyk/.conda/envs/watson/lib/python3.12/site-packages/asksageclient/client.py", line 46, in _request
    response.raise_for_status()
  File "/home/jupyter-zszewczyk/.conda/envs/watson/lib/python3.12/site-packages/requests/models.py", line 1026, in raise_for_status
    raise HTTPError(http_error_msg, response=self)
requests.exceptions.HTTPError: 503 Server Error: Service Temporarily Unavailable for url: https://api.genai.army.mil/user//get-token-with-api-key
2025-09-29 18:15:35 ERROR    __main__ :: [MAIN pid=66871 proc=MainProcess] Worker crashed: 503 Server Error: Service Temporarily Unavailable for url: https://api.genai.army.mil/user//get-token-with-api-key
2025-09-29 18:15:35 ERROR    asksageclient.client :: Http Error:
Traceback (most recent call last):
  File "/home/jupyter-zszewczyk/.conda/envs/watson/lib/python3.12/site-packages/asksageclient/client.py", line 46, in _request
    response.raise_for_status()
  File "/home/jupyter-zszewczyk/.conda/envs/watson/lib/python3.12/site-packages/requests/models.py", line 1026, in raise_for_status
    raise HTTPError(http_error_msg, response=self)
requests.exceptions.HTTPError: 503 Server Error: Service Temporarily Unavailable for url: https://api.genai.army.mil/user//get-token-with-api-key
2025-09-29 18:15:35 ERROR    __main__ :: [MAIN pid=66871 proc=MainProcess] Worker crashed: 503 Server Error: Service Temporarily Unavailable for url: https://api.genai.army.mil/user//get-token-with-api-key
2025-09-29 18:15:35 ERROR    asksageclient.client :: Http Error:
Traceback (most recent call last):
  File "/home/jupyter-zszewczyk/.conda/envs/watson/lib/python3.12/site-packages/asksageclient/client.py", line 46, in _request
    response.raise_for_status()
  File "/home/jupyter-zszewczyk/.conda/envs/watson/lib/python3.12/site-packages/requests/models.py", line 1026, in raise_for_status
    raise HTTPError(http_error_msg, response=self)
requests.exceptions.HTTPError: 503 Server Error: Service Temporarily Unavailable for url: https://api.genai.army.mil/user//get-token-with-api-key
2025-09-29 18:15:35 ERROR    __main__ :: [MAIN pid=66871 proc=MainProcess] Worker crashed: 503 Server Error: Service Temporarily Unavailable for url: https://api.genai.army.mil/user//get-token-with-api-key
2025-09-29 18:15:35 ERROR    asksageclient.client :: Http Error:
Traceback (most recent call last):
  File "/home/jupyter-zszewczyk/.conda/envs/watson/lib/python3.12/site-packages/asksageclient/client.py", line 46, in _request
    response.raise_for_status()
  File "/home/jupyter-zszewczyk/.conda/envs/watson/lib/python3.12/site-packages/requests/models.py", line 1026, in raise_for_status
    raise HTTPError(http_error_msg, response=self)
requests.exceptions.HTTPError: 503 Server Error: Service Temporarily Unavailable for url: https://api.genai.army.mil/user//get-token-with-api-key
2025-09-29 18:15:35 ERROR    __main__ :: [MAIN pid=66871 proc=MainProcess] Worker crashed: 503 Server Error: Service Temporarily Unavailable for url: https://api.genai.army.mil/user//get-token-with-api-key
2025-09-29 18:15:35 ERROR    asksageclient.client :: Http Error:
Traceback (most recent call last):
  File "/home/jupyter-zszewczyk/.conda/envs/watson/lib/python3.12/site-packages/asksageclient/client.py", line 46, in _request
    response.raise_for_status()
  File "/home/jupyter-zszewczyk/.conda/envs/watson/lib/python3.12/site-packages/requests/models.py", line 1026, in raise_for_status
    raise HTTPError(http_error_msg, response=self)
requests.exceptions.HTTPError: 503 Server Error: Service Temporarily Unavailable for url: https://api.genai.army.mil/user//get-token-with-api-key
2025-09-29 18:15:35 ERROR    __main__ :: [MAIN pid=66871 proc=MainProcess] Worker crashed: 503 Server Error: Service Temporarily Unavailable for url: https://api.genai.army.mil/user//get-token-with-api-key
2025-09-29 18:15:35 ERROR    asksageclient.client :: Http Error:
Traceback (most recent call last):
  File "/home/jupyter-zszewczyk/.conda/envs/watson/lib/python3.12/site-packages/asksageclient/client.py", line 46, in _request
    response.raise_for_status()
  File "/home/jupyter-zszewczyk/.conda/envs/watson/lib/python3.12/site-packages/requests/models.py", line 1026, in raise_for_status
    raise HTTPError(http_error_msg, response=self)
requests.exceptions.HTTPError: 503 Server Error: Service Temporarily Unavailable for url: https://api.genai.army.mil/user//get-token-with-api-key
2025-09-29 18:15:35 ERROR    __main__ :: [MAIN pid=66871 proc=MainProcess] Worker crashed: 503 Server Error: Service Temporarily Unavailable for url: https://api.genai.army.mil/user//get-token-with-api-key
2025-09-29 18:15:35 ERROR    asksageclient.client :: Http Error:
Traceback (most recent call last):
  File "/home/jupyter-zszewczyk/.conda/envs/watson/lib/python3.12/site-packages/asksageclient/client.py", line 46, in _request
    response.raise_for_status()
  File "/home/jupyter-zszewczyk/.conda/envs/watson/lib/python3.12/site-packages/requests/models.py", line 1026, in raise_for_status
    raise HTTPError(http_error_msg, response=self)
requests.exceptions.HTTPError: 503 Server Error: Service Temporarily Unavailable for url: https://api.genai.army.mil/user//get-token-with-api-key
2025-09-29 18:15:35 ERROR    __main__ :: [MAIN pid=66871 proc=MainProcess] Worker crashed: 503 Server Error: Service Temporarily Unavailable for url: https://api.genai.army.mil/user//get-token-with-api-key
2025-09-29 18:15:35 ERROR    asksageclient.client :: Http Error:
Traceback (most recent call last):
  File "/home/jupyter-zszewczyk/.conda/envs/watson/lib/python3.12/site-packages/asksageclient/client.py", line 46, in _request
    response.raise_for_status()
  File "/home/jupyter-zszewczyk/.conda/envs/watson/lib/python3.12/site-packages/requests/models.py", line 1026, in raise_for_status
    raise HTTPError(http_error_msg, response=self)
requests.exceptions.HTTPError: 503 Server Error: Service Temporarily Unavailable for url: https://api.genai.army.mil/user//get-token-with-api-key
2025-09-29 18:15:35 ERROR    __main__ :: [MAIN pid=66871 proc=MainProcess] Worker crashed: 503 Server Error: Service Temporarily Unavailable for url: https://api.genai.army.mil/user//get-token-with-api-key
2025-09-29 18:15:35 ERROR    asksageclient.client :: Http Error:
Traceback (most recent call last):
  File "/home/jupyter-zszewczyk/.conda/envs/watson/lib/python3.12/site-packages/asksageclient/client.py", line 46, in _request
    response.raise_for_status()
  File "/home/jupyter-zszewczyk/.conda/envs/watson/lib/python3.12/site-packages/requests/models.py", line 1026, in raise_for_status
    raise HTTPError(http_error_msg, response=self)
requests.exceptions.HTTPError: 503 Server Error: Service Temporarily Unavailable for url: https://api.genai.army.mil/user//get-token-with-api-key
2025-09-29 18:15:35 ERROR    __main__ :: [MAIN pid=66871 proc=MainProcess] Worker crashed: 503 Server Error: Service Temporarily Unavailable for url: https://api.genai.army.mil/user//get-token-with-api-key
2025-09-29 18:15:36 ERROR    asksageclient.client :: Http Error:
Traceback (most recent call last):
  File "/home/jupyter-zszewczyk/.conda/envs/watson/lib/python3.12/site-packages/asksageclient/client.py", line 46, in _request
    response.raise_for_status()
  File "/home/jupyter-zszewczyk/.conda/envs/watson/lib/python3.12/site-packages/requests/models.py", line 1026, in raise_for_status
    raise HTTPError(http_error_msg, response=self)
requests.exceptions.HTTPError: 503 Server Error: Service Temporarily Unavailable for url: https://api.genai.army.mil/user//get-token-with-api-key
2025-09-29 18:15:36 ERROR    __main__ :: [MAIN pid=66871 proc=MainProcess] Worker crashed: 503 Server Error: Service Temporarily Unavailable for url: https://api.genai.army.mil/user//get-token-with-api-key
2025-09-29 18:15:36 ERROR    asksageclient.client :: Http Error:
Traceback (most recent call last):
  File "/home/jupyter-zszewczyk/.conda/envs/watson/lib/python3.12/site-packages/asksageclient/client.py", line 46, in _request
    response.raise_for_status()
  File "/home/jupyter-zszewczyk/.conda/envs/watson/lib/python3.12/site-packages/requests/models.py", line 1026, in raise_for_status
    raise HTTPError(http_error_msg, response=self)
requests.exceptions.HTTPError: 503 Server Error: Service Temporarily Unavailable for url: https://api.genai.army.mil/user//get-token-with-api-key
2025-09-29 18:15:36 ERROR    __main__ :: [MAIN pid=66871 proc=MainProcess] Worker crashed: 503 Server Error: Service Temporarily Unavailable for url: https://api.genai.army.mil/user//get-token-with-api-key
2025-09-29 18:15:36 ERROR    asksageclient.client :: Http Error:
Traceback (most recent call last):
  File "/home/jupyter-zszewczyk/.conda/envs/watson/lib/python3.12/site-packages/asksageclient/client.py", line 46, in _request
    response.raise_for_status()
  File "/home/jupyter-zszewczyk/.conda/envs/watson/lib/python3.12/site-packages/requests/models.py", line 1026, in raise_for_status
    raise HTTPError(http_error_msg, response=self)
requests.exceptions.HTTPError: 503 Server Error: Service Temporarily Unavailable for url: https://api.genai.army.mil/user//get-token-with-api-key
2025-09-29 18:15:36 ERROR    __main__ :: [MAIN pid=66871 proc=MainProcess] Worker crashed: 503 Server Error: Service Temporarily Unavailable for url: https://api.genai.army.mil/user//get-token-with-api-key
2025-09-29 18:15:36 ERROR    asksageclient.client :: Http Error:
Traceback (most recent call last):
  File "/home/jupyter-zszewczyk/.conda/envs/watson/lib/python3.12/site-packages/asksageclient/client.py", line 46, in _request
    response.raise_for_status()
  File "/home/jupyter-zszewczyk/.conda/envs/watson/lib/python3.12/site-packages/requests/models.py", line 1026, in raise_for_status
    raise HTTPError(http_error_msg, response=self)
requests.exceptions.HTTPError: 503 Server Error: Service Temporarily Unavailable for url: https://api.genai.army.mil/user//get-token-with-api-key
2025-09-29 18:15:36 ERROR    __main__ :: [MAIN pid=66871 proc=MainProcess] Worker crashed: 503 Server Error: Service Temporarily Unavailable for url: https://api.genai.army.mil/user//get-token-with-api-key
2025-09-29 18:15:36 ERROR    asksageclient.client :: Http Error:
Traceback (most recent call last):
  File "/home/jupyter-zszewczyk/.conda/envs/watson/lib/python3.12/site-packages/asksageclient/client.py", line 46, in _request
    response.raise_for_status()
  File "/home/jupyter-zszewczyk/.conda/envs/watson/lib/python3.12/site-packages/requests/models.py", line 1026, in raise_for_status
    raise HTTPError(http_error_msg, response=self)
requests.exceptions.HTTPError: 503 Server Error: Service Temporarily Unavailable for url: https://api.genai.army.mil/user//get-token-with-api-key
2025-09-29 18:15:36 ERROR    __main__ :: [MAIN pid=66871 proc=MainProcess] Worker crashed: 503 Server Error: Service Temporarily Unavailable for url: https://api.genai.army.mil/user//get-token-with-api-key
2025-09-29 18:15:36 ERROR    asksageclient.client :: Http Error:
Traceback (most recent call last):
  File "/home/jupyter-zszewczyk/.conda/envs/watson/lib/python3.12/site-packages/asksageclient/client.py", line 46, in _request
    response.raise_for_status()
  File "/home/jupyter-zszewczyk/.conda/envs/watson/lib/python3.12/site-packages/requests/models.py", line 1026, in raise_for_status
    raise HTTPError(http_error_msg, response=self)
requests.exceptions.HTTPError: 503 Server Error: Service Temporarily Unavailable for url: https://api.genai.army.mil/user//get-token-with-api-key
2025-09-29 18:15:36 ERROR    __main__ :: [MAIN pid=66871 proc=MainProcess] Worker crashed: 503 Server Error: Service Temporarily Unavailable for url: https://api.genai.army.mil/user//get-token-with-api-key
2025-09-29 18:15:36 ERROR    asksageclient.client :: Http Error:
Traceback (most recent call last):
  File "/home/jupyter-zszewczyk/.conda/envs/watson/lib/python3.12/site-packages/asksageclient/client.py", line 46, in _request
    response.raise_for_status()
  File "/home/jupyter-zszewczyk/.conda/envs/watson/lib/python3.12/site-packages/requests/models.py", line 1026, in raise_for_status
    raise HTTPError(http_error_msg, response=self)
requests.exceptions.HTTPError: 503 Server Error: Service Temporarily Unavailable for url: https://api.genai.army.mil/user//get-token-with-api-key
2025-09-29 18:15:36 ERROR    __main__ :: [MAIN pid=66871 proc=MainProcess] Worker crashed: 503 Server Error: Service Temporarily Unavailable for url: https://api.genai.army.mil/user//get-token-with-api-key
2025-09-29 18:15:36 ERROR    asksageclient.client :: Http Error:
Traceback (most recent call last):
  File "/home/jupyter-zszewczyk/.conda/envs/watson/lib/python3.12/site-packages/asksageclient/client.py", line 46, in _request
    response.raise_for_status()
  File "/home/jupyter-zszewczyk/.conda/envs/watson/lib/python3.12/site-packages/requests/models.py", line 1026, in raise_for_status
    raise HTTPError(http_error_msg, response=self)
requests.exceptions.HTTPError: 503 Server Error: Service Temporarily Unavailable for url: https://api.genai.army.mil/user//get-token-with-api-key
2025-09-29 18:15:36 ERROR    __main__ :: [MAIN pid=66871 proc=MainProcess] Worker crashed: 503 Server Error: Service Temporarily Unavailable for url: https://api.genai.army.mil/user//get-token-with-api-key
2025-09-29 18:15:36 ERROR    asksageclient.client :: Http Error:
Traceback (most recent call last):
  File "/home/jupyter-zszewczyk/.conda/envs/watson/lib/python3.12/site-packages/asksageclient/client.py", line 46, in _request
    response.raise_for_status()
  File "/home/jupyter-zszewczyk/.conda/envs/watson/lib/python3.12/site-packages/requests/models.py", line 1026, in raise_for_status
    raise HTTPError(http_error_msg, response=self)
requests.exceptions.HTTPError: 503 Server Error: Service Temporarily Unavailable for url: https://api.genai.army.mil/user//get-token-with-api-key
2025-09-29 18:15:36 ERROR    __main__ :: [MAIN pid=66871 proc=MainProcess] Worker crashed: 503 Server Error: Service Temporarily Unavailable for url: https://api.genai.army.mil/user//get-token-with-api-key
2025-09-29 18:15:36 ERROR    asksageclient.client :: Http Error:
Traceback (most recent call last):
  File "/home/jupyter-zszewczyk/.conda/envs/watson/lib/python3.12/site-packages/asksageclient/client.py", line 46, in _request
    response.raise_for_status()
  File "/home/jupyter-zszewczyk/.conda/envs/watson/lib/python3.12/site-packages/requests/models.py", line 1026, in raise_for_status
    raise HTTPError(http_error_msg, response=self)
requests.exceptions.HTTPError: 503 Server Error: Service Temporarily Unavailable for url: https://api.genai.army.mil/user//get-token-with-api-key
2025-09-29 18:15:36 ERROR    __main__ :: [MAIN pid=66871 proc=MainProcess] Worker crashed: 503 Server Error: Service Temporarily Unavailable for url: https://api.genai.army.mil/user//get-token-with-api-key
2025-09-29 18:15:36 ERROR    asksageclient.client :: Http Error:
Traceback (most recent call last):
  File "/home/jupyter-zszewczyk/.conda/envs/watson/lib/python3.12/site-packages/asksageclient/client.py", line 46, in _request
    response.raise_for_status()
  File "/home/jupyter-zszewczyk/.conda/envs/watson/lib/python3.12/site-packages/requests/models.py", line 1026, in raise_for_status
    raise HTTPError(http_error_msg, response=self)
requests.exceptions.HTTPError: 503 Server Error: Service Temporarily Unavailable for url: https://api.genai.army.mil/user//get-token-with-api-key
2025-09-29 18:15:36 ERROR    __main__ :: [MAIN pid=66871 proc=MainProcess] Worker crashed: 503 Server Error: Service Temporarily Unavailable for url: https://api.genai.army.mil/user//get-token-with-api-key
2025-09-29 18:15:36 ERROR    asksageclient.client :: Http Error:
Traceback (most recent call last):
  File "/home/jupyter-zszewczyk/.conda/envs/watson/lib/python3.12/site-packages/asksageclient/client.py", line 46, in _request
    response.raise_for_status()
  File "/home/jupyter-zszewczyk/.conda/envs/watson/lib/python3.12/site-packages/requests/models.py", line 1026, in raise_for_status
    raise HTTPError(http_error_msg, response=self)
requests.exceptions.HTTPError: 503 Server Error: Service Temporarily Unavailable for url: https://api.genai.army.mil/user//get-token-with-api-key
2025-09-29 18:15:36 ERROR    __main__ :: [MAIN pid=66871 proc=MainProcess] Worker crashed: 503 Server Error: Service Temporarily Unavailable for url: https://api.genai.army.mil/user//get-token-with-api-key
2025-09-29 18:15:37 ERROR    asksageclient.client :: Http Error:
Traceback (most recent call last):
  File "/home/jupyter-zszewczyk/.conda/envs/watson/lib/python3.12/site-packages/asksageclient/client.py", line 46, in _request
    response.raise_for_status()
  File "/home/jupyter-zszewczyk/.conda/envs/watson/lib/python3.12/site-packages/requests/models.py", line 1026, in raise_for_status
    raise HTTPError(http_error_msg, response=self)
requests.exceptions.HTTPError: 503 Server Error: Service Temporarily Unavailable for url: https://api.genai.army.mil/user//get-token-with-api-key
2025-09-29 18:15:37 ERROR    __main__ :: [MAIN pid=66871 proc=MainProcess] Worker crashed: 503 Server Error: Service Temporarily Unavailable for url: https://api.genai.army.mil/user//get-token-with-api-key
2025-09-29 18:15:37 ERROR    asksageclient.client :: Http Error:
Traceback (most recent call last):
  File "/home/jupyter-zszewczyk/.conda/envs/watson/lib/python3.12/site-packages/asksageclient/client.py", line 46, in _request
    response.raise_for_status()
  File "/home/jupyter-zszewczyk/.conda/envs/watson/lib/python3.12/site-packages/requests/models.py", line 1026, in raise_for_status
    raise HTTPError(http_error_msg, response=self)
requests.exceptions.HTTPError: 503 Server Error: Service Temporarily Unavailable for url: https://api.genai.army.mil/user//get-token-with-api-key
2025-09-29 18:15:37 ERROR    __main__ :: [MAIN pid=66871 proc=MainProcess] Worker crashed: 503 Server Error: Service Temporarily Unavailable for url: https://api.genai.army.mil/user//get-token-with-api-key
2025-09-29 18:15:37 ERROR    asksageclient.client :: Http Error:
Traceback (most recent call last):
  File "/home/jupyter-zszewczyk/.conda/envs/watson/lib/python3.12/site-packages/asksageclient/client.py", line 46, in _request
    response.raise_for_status()
  File "/home/jupyter-zszewczyk/.conda/envs/watson/lib/python3.12/site-packages/requests/models.py", line 1026, in raise_for_status
    raise HTTPError(http_error_msg, response=self)
requests.exceptions.HTTPError: 503 Server Error: Service Temporarily Unavailable for url: https://api.genai.army.mil/user//get-token-with-api-key
2025-09-29 18:15:37 ERROR    __main__ :: [MAIN pid=66871 proc=MainProcess] Worker crashed: 503 Server Error: Service Temporarily Unavailable for url: https://api.genai.army.mil/user//get-token-with-api-key
2025-09-29 18:15:37 ERROR    asksageclient.client :: Http Error:
Traceback (most recent call last):
  File "/home/jupyter-zszewczyk/.conda/envs/watson/lib/python3.12/site-packages/asksageclient/client.py", line 46, in _request
    response.raise_for_status()
  File "/home/jupyter-zszewczyk/.conda/envs/watson/lib/python3.12/site-packages/requests/models.py", line 1026, in raise_for_status
    raise HTTPError(http_error_msg, response=self)
requests.exceptions.HTTPError: 503 Server Error: Service Temporarily Unavailable for url: https://api.genai.army.mil/user//get-token-with-api-key
2025-09-29 18:15:37 ERROR    __main__ :: [MAIN pid=66871 proc=MainProcess] Worker crashed: 503 Server Error: Service Temporarily Unavailable for url: https://api.genai.army.mil/user//get-token-with-api-key
2025-09-29 18:15:37 ERROR    asksageclient.client :: Http Error:
Traceback (most recent call last):
  File "/home/jupyter-zszewczyk/.conda/envs/watson/lib/python3.12/site-packages/asksageclient/client.py", line 46, in _request
    response.raise_for_status()
  File "/home/jupyter-zszewczyk/.conda/envs/watson/lib/python3.12/site-packages/requests/models.py", line 1026, in raise_for_status
    raise HTTPError(http_error_msg, response=self)
requests.exceptions.HTTPError: 503 Server Error: Service Temporarily Unavailable for url: https://api.genai.army.mil/user//get-token-with-api-key
2025-09-29 18:15:37 ERROR    __main__ :: [MAIN pid=66871 proc=MainProcess] Worker crashed: 503 Server Error: Service Temporarily Unavailable for url: https://api.genai.army.mil/user//get-token-with-api-key
2025-09-29 18:15:37 ERROR    asksageclient.client :: Http Error:
Traceback (most recent call last):
  File "/home/jupyter-zszewczyk/.conda/envs/watson/lib/python3.12/site-packages/asksageclient/client.py", line 46, in _request
    response.raise_for_status()
  File "/home/jupyter-zszewczyk/.conda/envs/watson/lib/python3.12/site-packages/requests/models.py", line 1026, in raise_for_status
    raise HTTPError(http_error_msg, response=self)
requests.exceptions.HTTPError: 503 Server Error: Service Temporarily Unavailable for url: https://api.genai.army.mil/user//get-token-with-api-key
2025-09-29 18:15:37 ERROR    __main__ :: [MAIN pid=66871 proc=MainProcess] Worker crashed: 503 Server Error: Service Temporarily Unavailable for url: https://api.genai.army.mil/user//get-token-with-api-key
2025-09-29 18:15:37 ERROR    asksageclient.client :: Http Error:
Traceback (most recent call last):
  File "/home/jupyter-zszewczyk/.conda/envs/watson/lib/python3.12/site-packages/asksageclient/client.py", line 46, in _request
    response.raise_for_status()
  File "/home/jupyter-zszewczyk/.conda/envs/watson/lib/python3.12/site-packages/requests/models.py", line 1026, in raise_for_status
    raise HTTPError(http_error_msg, response=self)
requests.exceptions.HTTPError: 503 Server Error: Service Temporarily Unavailable for url: https://api.genai.army.mil/user//get-token-with-api-key
2025-09-29 18:15:37 ERROR    __main__ :: [MAIN pid=66871 proc=MainProcess] Worker crashed: 503 Server Error: Service Temporarily Unavailable for url: https://api.genai.army.mil/user//get-token-with-api-key
2025-09-29 18:15:37 ERROR    asksageclient.client :: Http Error:
Traceback (most recent call last):
  File "/home/jupyter-zszewczyk/.conda/envs/watson/lib/python3.12/site-packages/asksageclient/client.py", line 46, in _request
    response.raise_for_status()
  File "/home/jupyter-zszewczyk/.conda/envs/watson/lib/python3.12/site-packages/requests/models.py", line 1026, in raise_for_status
    raise HTTPError(http_error_msg, response=self)
requests.exceptions.HTTPError: 503 Server Error: Service Temporarily Unavailable for url: https://api.genai.army.mil/user//get-token-with-api-key
2025-09-29 18:15:37 ERROR    __main__ :: [MAIN pid=66871 proc=MainProcess] Worker crashed: 503 Server Error: Service Temporarily Unavailable for url: https://api.genai.army.mil/user//get-token-with-api-key
2025-09-29 18:15:37 ERROR    asksageclient.client :: Http Error:
Traceback (most recent call last):
  File "/home/jupyter-zszewczyk/.conda/envs/watson/lib/python3.12/site-packages/asksageclient/client.py", line 46, in _request
    response.raise_for_status()
  File "/home/jupyter-zszewczyk/.conda/envs/watson/lib/python3.12/site-packages/requests/models.py", line 1026, in raise_for_status
    raise HTTPError(http_error_msg, response=self)
requests.exceptions.HTTPError: 503 Server Error: Service Temporarily Unavailable for url: https://api.genai.army.mil/user//get-token-with-api-key
2025-09-29 18:15:37 ERROR    __main__ :: [MAIN pid=66871 proc=MainProcess] Worker crashed: 503 Server Error: Service Temporarily Unavailable for url: https://api.genai.army.mil/user//get-token-with-api-key
2025-09-29 18:15:37 ERROR    asksageclient.client :: Http Error:
Traceback (most recent call last):
  File "/home/jupyter-zszewczyk/.conda/envs/watson/lib/python3.12/site-packages/asksageclient/client.py", line 46, in _request
    response.raise_for_status()
  File "/home/jupyter-zszewczyk/.conda/envs/watson/lib/python3.12/site-packages/requests/models.py", line 1026, in raise_for_status
    raise HTTPError(http_error_msg, response=self)
requests.exceptions.HTTPError: 503 Server Error: Service Temporarily Unavailable for url: https://api.genai.army.mil/user//get-token-with-api-key
2025-09-29 18:15:37 ERROR    __main__ :: [MAIN pid=66871 proc=MainProcess] Worker crashed: 503 Server Error: Service Temporarily Unavailable for url: https://api.genai.army.mil/user//get-token-with-api-key
2025-09-29 18:15:37 ERROR    asksageclient.client :: Http Error:
Traceback (most recent call last):
  File "/home/jupyter-zszewczyk/.conda/envs/watson/lib/python3.12/site-packages/asksageclient/client.py", line 46, in _request
    response.raise_for_status()
  File "/home/jupyter-zszewczyk/.conda/envs/watson/lib/python3.12/site-packages/requests/models.py", line 1026, in raise_for_status
    raise HTTPError(http_error_msg, response=self)
requests.exceptions.HTTPError: 503 Server Error: Service Temporarily Unavailable for url: https://api.genai.army.mil/user//get-token-with-api-key
2025-09-29 18:15:37 ERROR    __main__ :: [MAIN pid=66871 proc=MainProcess] Worker crashed: 503 Server Error: Service Temporarily Unavailable for url: https://api.genai.army.mil/user//get-token-with-api-key
2025-09-29 18:15:37 ERROR    asksageclient.client :: Http Error:
Traceback (most recent call last):
  File "/home/jupyter-zszewczyk/.conda/envs/watson/lib/python3.12/site-packages/asksageclient/client.py", line 46, in _request
    response.raise_for_status()
  File "/home/jupyter-zszewczyk/.conda/envs/watson/lib/python3.12/site-packages/requests/models.py", line 1026, in raise_for_status
    raise HTTPError(http_error_msg, response=self)
requests.exceptions.HTTPError: 503 Server Error: Service Temporarily Unavailable for url: https://api.genai.army.mil/user//get-token-with-api-key
2025-09-29 18:15:37 ERROR    __main__ :: [MAIN pid=66871 proc=MainProcess] Worker crashed: 503 Server Error: Service Temporarily Unavailable for url: https://api.genai.army.mil/user//get-token-with-api-key
2025-09-29 18:15:38 ERROR    asksageclient.client :: Http Error:
Traceback (most recent call last):
  File "/home/jupyter-zszewczyk/.conda/envs/watson/lib/python3.12/site-packages/asksageclient/client.py", line 46, in _request
    response.raise_for_status()
  File "/home/jupyter-zszewczyk/.conda/envs/watson/lib/python3.12/site-packages/requests/models.py", line 1026, in raise_for_status
    raise HTTPError(http_error_msg, response=self)
requests.exceptions.HTTPError: 503 Server Error: Service Temporarily Unavailable for url: https://api.genai.army.mil/user//get-token-with-api-key
2025-09-29 18:15:38 ERROR    __main__ :: [MAIN pid=66871 proc=MainProcess] Worker crashed: 503 Server Error: Service Temporarily Unavailable for url: https://api.genai.army.mil/user//get-token-with-api-key
2025-09-29 18:15:38 ERROR    asksageclient.client :: Http Error:
Traceback (most recent call last):
  File "/home/jupyter-zszewczyk/.conda/envs/watson/lib/python3.12/site-packages/asksageclient/client.py", line 46, in _request
    response.raise_for_status()
  File "/home/jupyter-zszewczyk/.conda/envs/watson/lib/python3.12/site-packages/requests/models.py", line 1026, in raise_for_status
    raise HTTPError(http_error_msg, response=self)
requests.exceptions.HTTPError: 503 Server Error: Service Temporarily Unavailable for url: https://api.genai.army.mil/user//get-token-with-api-key
2025-09-29 18:15:38 ERROR    __main__ :: [MAIN pid=66871 proc=MainProcess] Worker crashed: 503 Server Error: Service Temporarily Unavailable for url: https://api.genai.army.mil/user//get-token-with-api-key
2025-09-29 18:15:38 ERROR    asksageclient.client :: Http Error:
Traceback (most recent call last):
  File "/home/jupyter-zszewczyk/.conda/envs/watson/lib/python3.12/site-packages/asksageclient/client.py", line 46, in _request
    response.raise_for_status()
  File "/home/jupyter-zszewczyk/.conda/envs/watson/lib/python3.12/site-packages/requests/models.py", line 1026, in raise_for_status
    raise HTTPError(http_error_msg, response=self)
requests.exceptions.HTTPError: 503 Server Error: Service Temporarily Unavailable for url: https://api.genai.army.mil/user//get-token-with-api-key
2025-09-29 18:15:38 ERROR    __main__ :: [MAIN pid=66871 proc=MainProcess] Worker crashed: 503 Server Error: Service Temporarily Unavailable for url: https://api.genai.army.mil/user//get-token-with-api-key
2025-09-29 18:15:38 ERROR    asksageclient.client :: Http Error:
Traceback (most recent call last):
  File "/home/jupyter-zszewczyk/.conda/envs/watson/lib/python3.12/site-packages/asksageclient/client.py", line 46, in _request
    response.raise_for_status()
  File "/home/jupyter-zszewczyk/.conda/envs/watson/lib/python3.12/site-packages/requests/models.py", line 1026, in raise_for_status
    raise HTTPError(http_error_msg, response=self)
requests.exceptions.HTTPError: 503 Server Error: Service Temporarily Unavailable for url: https://api.genai.army.mil/user//get-token-with-api-key
2025-09-29 18:15:38 ERROR    __main__ :: [MAIN pid=66871 proc=MainProcess] Worker crashed: 503 Server Error: Service Temporarily Unavailable for url: https://api.genai.army.mil/user//get-token-with-api-key
2025-09-29 18:15:38 ERROR    asksageclient.client :: Http Error:
Traceback (most recent call last):
  File "/home/jupyter-zszewczyk/.conda/envs/watson/lib/python3.12/site-packages/asksageclient/client.py", line 46, in _request
    response.raise_for_status()
  File "/home/jupyter-zszewczyk/.conda/envs/watson/lib/python3.12/site-packages/requests/models.py", line 1026, in raise_for_status
    raise HTTPError(http_error_msg, response=self)
requests.exceptions.HTTPError: 503 Server Error: Service Temporarily Unavailable for url: https://api.genai.army.mil/user//get-token-with-api-key
2025-09-29 18:15:38 ERROR    __main__ :: [MAIN pid=66871 proc=MainProcess] Worker crashed: 503 Server Error: Service Temporarily Unavailable for url: https://api.genai.army.mil/user//get-token-with-api-key
2025-09-29 18:15:38 ERROR    asksageclient.client :: Http Error:
Traceback (most recent call last):
  File "/home/jupyter-zszewczyk/.conda/envs/watson/lib/python3.12/site-packages/asksageclient/client.py", line 46, in _request
    response.raise_for_status()
  File "/home/jupyter-zszewczyk/.conda/envs/watson/lib/python3.12/site-packages/requests/models.py", line 1026, in raise_for_status
    raise HTTPError(http_error_msg, response=self)
requests.exceptions.HTTPError: 503 Server Error: Service Temporarily Unavailable for url: https://api.genai.army.mil/user//get-token-with-api-key
2025-09-29 18:15:38 ERROR    __main__ :: [MAIN pid=66871 proc=MainProcess] Worker crashed: 503 Server Error: Service Temporarily Unavailable for url: https://api.genai.army.mil/user//get-token-with-api-key
2025-09-29 18:15:38 ERROR    asksageclient.client :: Http Error:
Traceback (most recent call last):
  File "/home/jupyter-zszewczyk/.conda/envs/watson/lib/python3.12/site-packages/asksageclient/client.py", line 46, in _request
    response.raise_for_status()
  File "/home/jupyter-zszewczyk/.conda/envs/watson/lib/python3.12/site-packages/requests/models.py", line 1026, in raise_for_status
    raise HTTPError(http_error_msg, response=self)
requests.exceptions.HTTPError: 503 Server Error: Service Temporarily Unavailable for url: https://api.genai.army.mil/user//get-token-with-api-key
2025-09-29 18:15:38 ERROR    __main__ :: [MAIN pid=66871 proc=MainProcess] Worker crashed: 503 Server Error: Service Temporarily Unavailable for url: https://api.genai.army.mil/user//get-token-with-api-key
2025-09-29 18:15:38 ERROR    asksageclient.client :: Http Error:
Traceback (most recent call last):
  File "/home/jupyter-zszewczyk/.conda/envs/watson/lib/python3.12/site-packages/asksageclient/client.py", line 46, in _request
    response.raise_for_status()
  File "/home/jupyter-zszewczyk/.conda/envs/watson/lib/python3.12/site-packages/requests/models.py", line 1026, in raise_for_status
    raise HTTPError(http_error_msg, response=self)
requests.exceptions.HTTPError: 503 Server Error: Service Temporarily Unavailable for url: https://api.genai.army.mil/user//get-token-with-api-key
2025-09-29 18:15:38 ERROR    __main__ :: [MAIN pid=66871 proc=MainProcess] Worker crashed: 503 Server Error: Service Temporarily Unavailable for url: https://api.genai.army.mil/user//get-token-with-api-key
2025-09-29 18:15:38 ERROR    asksageclient.client :: Http Error:
Traceback (most recent call last):
  File "/home/jupyter-zszewczyk/.conda/envs/watson/lib/python3.12/site-packages/asksageclient/client.py", line 46, in _request
    response.raise_for_status()
  File "/home/jupyter-zszewczyk/.conda/envs/watson/lib/python3.12/site-packages/requests/models.py", line 1026, in raise_for_status
    raise HTTPError(http_error_msg, response=self)
requests.exceptions.HTTPError: 503 Server Error: Service Temporarily Unavailable for url: https://api.genai.army.mil/user//get-token-with-api-key
2025-09-29 18:15:38 ERROR    __main__ :: [MAIN pid=66871 proc=MainProcess] Worker crashed: 503 Server Error: Service Temporarily Unavailable for url: https://api.genai.army.mil/user//get-token-with-api-key
2025-09-29 18:15:38 ERROR    asksageclient.client :: Http Error:
Traceback (most recent call last):
  File "/home/jupyter-zszewczyk/.conda/envs/watson/lib/python3.12/site-packages/asksageclient/client.py", line 46, in _request
    response.raise_for_status()
  File "/home/jupyter-zszewczyk/.conda/envs/watson/lib/python3.12/site-packages/requests/models.py", line 1026, in raise_for_status
    raise HTTPError(http_error_msg, response=self)
requests.exceptions.HTTPError: 503 Server Error: Service Temporarily Unavailable for url: https://api.genai.army.mil/user//get-token-with-api-key
2025-09-29 18:15:38 ERROR    __main__ :: [MAIN pid=66871 proc=MainProcess] Worker crashed: 503 Server Error: Service Temporarily Unavailable for url: https://api.genai.army.mil/user//get-token-with-api-key
2025-09-29 18:15:38 ERROR    asksageclient.client :: Http Error:
Traceback (most recent call last):
  File "/home/jupyter-zszewczyk/.conda/envs/watson/lib/python3.12/site-packages/asksageclient/client.py", line 46, in _request
    response.raise_for_status()
  File "/home/jupyter-zszewczyk/.conda/envs/watson/lib/python3.12/site-packages/requests/models.py", line 1026, in raise_for_status
    raise HTTPError(http_error_msg, response=self)
requests.exceptions.HTTPError: 503 Server Error: Service Temporarily Unavailable for url: https://api.genai.army.mil/user//get-token-with-api-key
2025-09-29 18:15:38 ERROR    __main__ :: [MAIN pid=66871 proc=MainProcess] Worker crashed: 503 Server Error: Service Temporarily Unavailable for url: https://api.genai.army.mil/user//get-token-with-api-key
2025-09-29 18:15:39 ERROR    asksageclient.client :: Http Error:
Traceback (most recent call last):
  File "/home/jupyter-zszewczyk/.conda/envs/watson/lib/python3.12/site-packages/asksageclient/client.py", line 46, in _request
    response.raise_for_status()
  File "/home/jupyter-zszewczyk/.conda/envs/watson/lib/python3.12/site-packages/requests/models.py", line 1026, in raise_for_status
    raise HTTPError(http_error_msg, response=self)
requests.exceptions.HTTPError: 503 Server Error: Service Temporarily Unavailable for url: https://api.genai.army.mil/user//get-token-with-api-key
2025-09-29 18:15:39 ERROR    __main__ :: [MAIN pid=66871 proc=MainProcess] Worker crashed: 503 Server Error: Service Temporarily Unavailable for url: https://api.genai.army.mil/user//get-token-with-api-key
